package com.wuppy.samsmod;

import java.util.Random;

import net.minecraft.entity.monster.EntityZombie;
import net.minecraft.init.Blocks;
import net.minecraft.tileentity.TileEntityMobSpawner;
import net.minecraft.world.World;
import net.minecraft.world.gen.feature.WorldGenerator;

public class WorldGenSamDungeon extends WorldGenerator
{
	public boolean generate(World world, Random rand, int x, int y, int z) 
	{
		world.setBlock(x + 0, y + 0, z + 0, SamsMod.samstone, 1, 2);
		world.setBlock(x + 0, y + 0, z + 1, SamsMod.samstone, 1, 2);
		world.setBlock(x + 0, y + 0, z + 2, SamsMod.samstone, 1, 2);
		world.setBlock(x + 0, y + 0, z + 3, SamsMod.samstone, 1, 2);
		world.setBlock(x + 0, y + 0, z + 4, SamsMod.samstone, 1, 2);
		world.setBlock(x + 0, y + 0, z + 5, SamsMod.samstone, 1, 2);
		world.setBlock(x + 0, y + 0, z + 6, SamsMod.samstone, 1, 2);
		world.setBlock(x + 0, y + 0, z + 7, SamsMod.samstone, 1, 2);
		world.setBlock(x + 0, y + 0, z + 8, SamsMod.samstone, 1, 2);
		world.setBlock(x + 0, y + 0, z + 9, SamsMod.samstone, 1, 2);
		world.setBlock(x + 0, y + 0, z + 10, SamsMod.samstone, 1, 2);
		world.setBlock(x + 0, y + 1, z + 0, SamsMod.samstone, 1, 2);
		world.setBlock(x + 0, y + 1, z + 1, SamsMod.samstone, 1, 2);
		world.setBlock(x + 0, y + 1, z + 2, SamsMod.samstone, 1, 2);
		world.setBlock(x + 0, y + 1, z + 3, SamsMod.samstone, 1, 2);
		world.setBlock(x + 0, y + 1, z + 4, SamsMod.samstone, 1, 2);
		world.setBlock(x + 0, y + 1, z + 5, SamsMod.samstone, 1, 2);
		world.setBlock(x + 0, y + 1, z + 6, SamsMod.samstone, 1, 2);
		world.setBlock(x + 0, y + 1, z + 7, SamsMod.samstone, 1, 2);
		world.setBlock(x + 0, y + 1, z + 8, SamsMod.samstone, 1, 2);
		world.setBlock(x + 0, y + 1, z + 9, SamsMod.samstone, 1, 2);
		world.setBlock(x + 0, y + 1, z + 10, SamsMod.samstone, 1, 2);
		world.setBlock(x + 0, y + 2, z + 0, SamsMod.samstone, 1, 2);
		world.setBlock(x + 0, y + 2, z + 1, SamsMod.samstone, 1, 2);
		world.setBlock(x + 0, y + 2, z + 2, SamsMod.samstone, 1, 2);
		world.setBlock(x + 0, y + 2, z + 3, SamsMod.samstone, 1, 2);
		world.setBlock(x + 0, y + 2, z + 4, SamsMod.samstone, 1, 2);
		world.setBlock(x + 0, y + 2, z + 5, SamsMod.samstone, 1, 2);
		world.setBlock(x + 0, y + 2, z + 6, SamsMod.samstone, 1, 2);
		world.setBlock(x + 0, y + 2, z + 7, SamsMod.samstone, 1, 2);
		world.setBlock(x + 0, y + 2, z + 8, SamsMod.samstone, 1, 2);
		world.setBlock(x + 0, y + 2, z + 9, SamsMod.samstone, 1, 2);
		world.setBlock(x + 0, y + 2, z + 10, SamsMod.samstone, 1, 2);
		world.setBlock(x + 0, y + 3, z + 0, SamsMod.samstone, 1, 2);
		world.setBlock(x + 0, y + 3, z + 1, SamsMod.samstone, 1, 2);
		world.setBlock(x + 0, y + 3, z + 2, SamsMod.samstone, 1, 2);
		world.setBlock(x + 0, y + 3, z + 3, SamsMod.samstone, 1, 2);
		world.setBlock(x + 0, y + 3, z + 4, SamsMod.samstone, 1, 2);
		world.setBlock(x + 0, y + 3, z + 5, SamsMod.samstone, 1, 2);
		world.setBlock(x + 0, y + 3, z + 6, SamsMod.samstone, 1, 2);
		world.setBlock(x + 0, y + 3, z + 7, SamsMod.samstone, 1, 2);
		world.setBlock(x + 0, y + 3, z + 8, SamsMod.samstone, 1, 2);
		world.setBlock(x + 0, y + 3, z + 9, SamsMod.samstone, 1, 2);
		world.setBlock(x + 0, y + 3, z + 10, SamsMod.samstone, 1, 2);
		world.setBlock(x + 0, y + 4, z + 0, SamsMod.samstone, 1, 2);
		world.setBlock(x + 0, y + 4, z + 1, SamsMod.samstone, 1, 2);
		world.setBlock(x + 0, y + 4, z + 2, SamsMod.samstone, 1, 2);
		world.setBlock(x + 0, y + 4, z + 3, SamsMod.samstone, 1, 2);
		world.setBlock(x + 0, y + 4, z + 4, SamsMod.samstone, 1, 2);
		world.setBlock(x + 0, y + 4, z + 5, SamsMod.samstone, 1, 2);
		world.setBlock(x + 0, y + 4, z + 6, SamsMod.samstone, 1, 2);
		world.setBlock(x + 0, y + 4, z + 7, SamsMod.samstone, 1, 2);
		world.setBlock(x + 0, y + 4, z + 8, SamsMod.samstone, 1, 2);
		world.setBlock(x + 0, y + 4, z + 9, SamsMod.samstone, 1, 2);
		world.setBlock(x + 0, y + 4, z + 10, SamsMod.samstone, 1, 2);
		world.setBlock(x + 0, y + 5, z + 0, SamsMod.samstone, 1, 2);
		world.setBlock(x + 0, y + 5, z + 1, SamsMod.samstone, 1, 2);
		world.setBlock(x + 0, y + 5, z + 2, SamsMod.samstone, 1, 2);
		world.setBlock(x + 0, y + 5, z + 3, SamsMod.samstone, 1, 2);
		world.setBlock(x + 0, y + 5, z + 4, SamsMod.samstone, 1, 2);
		world.setBlock(x + 0, y + 5, z + 5, SamsMod.samstone, 1, 2);
		world.setBlock(x + 0, y + 5, z + 6, SamsMod.samstone, 1, 2);
		world.setBlock(x + 0, y + 5, z + 7, SamsMod.samstone, 1, 2);
		world.setBlock(x + 0, y + 5, z + 8, SamsMod.samstone, 1, 2);
		world.setBlock(x + 0, y + 5, z + 9, SamsMod.samstone, 1, 2);
		world.setBlock(x + 0, y + 5, z + 10, SamsMod.samstone, 1, 2);
		world.setBlock(x + 1, y + 0, z + 0, SamsMod.samstone, 1, 2);
		world.setBlock(x + 1, y + 0, z + 1, SamsMod.samstone, 1, 2);
		world.setBlock(x + 1, y + 0, z + 2, SamsMod.samstone, 1, 2);
		world.setBlock(x + 1, y + 0, z + 3, SamsMod.samstone, 1, 2);
		world.setBlock(x + 1, y + 0, z + 4, SamsMod.samstone, 1, 2);
		world.setBlock(x + 1, y + 0, z + 5, SamsMod.samstone, 1, 2);
		world.setBlock(x + 1, y + 0, z + 6, SamsMod.samstone, 1, 2);
		world.setBlock(x + 1, y + 0, z + 7, SamsMod.samstone, 1, 2);
		world.setBlock(x + 1, y + 0, z + 8, SamsMod.samstone, 1, 2);
		world.setBlock(x + 1, y + 0, z + 9, SamsMod.samstone, 1, 2);
		world.setBlock(x + 1, y + 0, z + 10, SamsMod.samstone, 1, 2);
		world.setBlock(x + 1, y + 1, z + 0, SamsMod.samstone, 1, 2);
		world.setBlock(x + 1, y + 1, z + 1, Blocks.air);
		world.setBlock(x + 1, y + 1, z + 2, Blocks.air);
		world.setBlock(x + 1, y + 1, z + 3, Blocks.air);
		world.setBlock(x + 1, y + 1, z + 4, Blocks.air);
		world.setBlock(x + 1, y + 1, z + 5, SamsMod.samstone, 1, 2);
		world.setBlock(x + 1, y + 1, z + 6, Blocks.air);
		world.setBlock(x + 1, y + 1, z + 7, Blocks.air);
		world.setBlock(x + 1, y + 1, z + 8, Blocks.air);
		world.setBlock(x + 1, y + 1, z + 9, Blocks.air);
		world.setBlock(x + 1, y + 1, z + 10, SamsMod.samstone, 1, 2);
		world.setBlock(x + 1, y + 2, z + 0, SamsMod.samstone, 1, 2);
		world.setBlock(x + 1, y + 2, z + 1, Blocks.air);
		world.setBlock(x + 1, y + 2, z + 2, Blocks.air);
		world.setBlock(x + 1, y + 2, z + 3, Blocks.air);
		world.setBlock(x + 1, y + 2, z + 4, Blocks.air);
		world.setBlock(x + 1, y + 2, z + 5, SamsMod.samstone, 1, 2);
		world.setBlock(x + 1, y + 2, z + 6, Blocks.air);
		world.setBlock(x + 1, y + 2, z + 7, Blocks.air);
		world.setBlock(x + 1, y + 2, z + 8, Blocks.air);
		world.setBlock(x + 1, y + 2, z + 9, Blocks.air);
		world.setBlock(x + 1, y + 2, z + 10, SamsMod.samstone, 1, 2);
		world.setBlock(x + 1, y + 3, z + 0, SamsMod.samstone, 1, 2);
		world.setBlock(x + 1, y + 3, z + 1, Blocks.air);
		world.setBlock(x + 1, y + 3, z + 2, Blocks.air);
		world.setBlock(x + 1, y + 3, z + 3, Blocks.air);
		world.setBlock(x + 1, y + 3, z + 4, Blocks.air);
		world.setBlock(x + 1, y + 3, z + 5, SamsMod.samstone, 1, 2);
		world.setBlock(x + 1, y + 3, z + 6, Blocks.air);
		world.setBlock(x + 1, y + 3, z + 7, Blocks.air);
		world.setBlock(x + 1, y + 3, z + 8, Blocks.air);
		world.setBlock(x + 1, y + 3, z + 9, Blocks.air);
		world.setBlock(x + 1, y + 3, z + 10, SamsMod.samstone, 1, 2);
		world.setBlock(x + 1, y + 4, z + 0, SamsMod.samstone, 1, 2);
		world.setBlock(x + 1, y + 4, z + 1, Blocks.air);
		world.setBlock(x + 1, y + 4, z + 2, Blocks.air);
		world.setBlock(x + 1, y + 4, z + 3, Blocks.air);
		world.setBlock(x + 1, y + 4, z + 4, Blocks.air);
		world.setBlock(x + 1, y + 4, z + 5, Blocks.air);
		world.setBlock(x + 1, y + 4, z + 6, Blocks.air);
		world.setBlock(x + 1, y + 4, z + 7, Blocks.air);
		world.setBlock(x + 1, y + 4, z + 8, Blocks.air);
		world.setBlock(x + 1, y + 4, z + 9, Blocks.air);
		world.setBlock(x + 1, y + 4, z + 10, SamsMod.samstone, 1, 2);
		world.setBlock(x + 1, y + 5, z + 0, SamsMod.samstone, 1, 2);
		world.setBlock(x + 1, y + 5, z + 1, SamsMod.samstone, 1, 2);
		world.setBlock(x + 1, y + 5, z + 2, SamsMod.samstone, 1, 2);
		world.setBlock(x + 1, y + 5, z + 3, SamsMod.samstone, 1, 2);
		world.setBlock(x + 1, y + 5, z + 4, SamsMod.samstone, 1, 2);
		world.setBlock(x + 1, y + 5, z + 5, SamsMod.samstone, 1, 2);
		world.setBlock(x + 1, y + 5, z + 6, SamsMod.samstone, 1, 2);
		world.setBlock(x + 1, y + 5, z + 7, SamsMod.samstone, 1, 2);
		world.setBlock(x + 1, y + 5, z + 8, SamsMod.samstone, 1, 2);
		world.setBlock(x + 1, y + 5, z + 9, SamsMod.samstone, 1, 2);
		world.setBlock(x + 1, y + 5, z + 10, SamsMod.samstone, 1, 2);
		world.setBlock(x + 2, y + 0, z + 0, SamsMod.samstone, 1, 2);
		world.setBlock(x + 2, y + 0, z + 1, SamsMod.samstone, 1, 2);
		world.setBlock(x + 2, y + 0, z + 2, SamsMod.samstone, 1, 2);
		world.setBlock(x + 2, y + 0, z + 3, SamsMod.samstone, 1, 2);
		world.setBlock(x + 2, y + 0, z + 4, SamsMod.samstone, 1, 2);
		world.setBlock(x + 2, y + 0, z + 5, SamsMod.samstone, 1, 2);
		world.setBlock(x + 2, y + 0, z + 6, SamsMod.samstone, 1, 2);
		world.setBlock(x + 2, y + 0, z + 7, SamsMod.samstone, 1, 2);
		world.setBlock(x + 2, y + 0, z + 8, SamsMod.samstone, 1, 2);
		world.setBlock(x + 2, y + 0, z + 9, SamsMod.samstone, 1, 2);
		world.setBlock(x + 2, y + 0, z + 10, SamsMod.samstone, 1, 2);
		world.setBlock(x + 2, y + 1, z + 0, SamsMod.samstone, 1, 2);
		world.setBlock(x + 2, y + 1, z + 1, Blocks.air);
		world.setBlock(x + 2, y + 1, z + 2, Blocks.air);
		world.setBlock(x + 2, y + 1, z + 3, Blocks.air);
		world.setBlock(x + 2, y + 1, z + 4, Blocks.air);
		world.setBlock(x + 2, y + 1, z + 5, SamsMod.samstone, 1, 2);
		world.setBlock(x + 2, y + 1, z + 6, Blocks.air);
		world.setBlock(x + 2, y + 1, z + 7, Blocks.air);
		world.setBlock(x + 2, y + 1, z + 8, Blocks.air);
		world.setBlock(x + 2, y + 1, z + 9, Blocks.air);
		world.setBlock(x + 2, y + 1, z + 10, SamsMod.samstone, 1, 2);
		world.setBlock(x + 2, y + 2, z + 0, SamsMod.samstone, 1, 2);
		world.setBlock(x + 2, y + 2, z + 1, Blocks.air);
		world.setBlock(x + 2, y + 2, z + 2, Blocks.air);
		world.setBlock(x + 2, y + 2, z + 3, Blocks.air);
		world.setBlock(x + 2, y + 2, z + 4, Blocks.air);
		world.setBlock(x + 2, y + 2, z + 5, Blocks.air);
		world.setBlock(x + 2, y + 2, z + 6, Blocks.air);
		world.setBlock(x + 2, y + 2, z + 7, Blocks.air);
		world.setBlock(x + 2, y + 2, z + 8, Blocks.air);
		world.setBlock(x + 2, y + 2, z + 9, Blocks.air);
		world.setBlock(x + 2, y + 2, z + 10, SamsMod.samstone, 1, 2);
		world.setBlock(x + 2, y + 3, z + 0, SamsMod.samstone, 1, 2);
		world.setBlock(x + 2, y + 3, z + 1, Blocks.air);
		world.setBlock(x + 2, y + 3, z + 2, Blocks.air);
		world.setBlock(x + 2, y + 3, z + 3, Blocks.air);
		world.setBlock(x + 2, y + 3, z + 4, Blocks.air);
		world.setBlock(x + 2, y + 3, z + 5, Blocks.air);
		world.setBlock(x + 2, y + 3, z + 6, Blocks.air);
		world.setBlock(x + 2, y + 3, z + 7, Blocks.air);
		world.setBlock(x + 2, y + 3, z + 8, Blocks.air);
		world.setBlock(x + 2, y + 3, z + 9, Blocks.air);
		world.setBlock(x + 2, y + 3, z + 10, SamsMod.samstone, 1, 2);
		world.setBlock(x + 2, y + 4, z + 0, SamsMod.samstone, 1, 2);
		world.setBlock(x + 2, y + 4, z + 1, Blocks.air);
		world.setBlock(x + 2, y + 4, z + 2, Blocks.air);
		world.setBlock(x + 2, y + 4, z + 3, Blocks.air);
		world.setBlock(x + 2, y + 4, z + 4, Blocks.air);
		world.setBlock(x + 2, y + 4, z + 5, Blocks.air);
		world.setBlock(x + 2, y + 4, z + 6, Blocks.air);
		world.setBlock(x + 2, y + 4, z + 7, Blocks.air);
		world.setBlock(x + 2, y + 4, z + 8, Blocks.air);
		world.setBlock(x + 2, y + 4, z + 9, Blocks.air);
		world.setBlock(x + 2, y + 4, z + 10, SamsMod.samstone, 1, 2);
		world.setBlock(x + 2, y + 5, z + 0, SamsMod.samstone, 1, 2);
		world.setBlock(x + 2, y + 5, z + 1, SamsMod.samstone, 1, 2);
		world.setBlock(x + 2, y + 5, z + 2, SamsMod.samstone, 1, 2);
		world.setBlock(x + 2, y + 5, z + 3, SamsMod.samstone, 1, 2);
		world.setBlock(x + 2, y + 5, z + 4, SamsMod.samstone, 1, 2);
		world.setBlock(x + 2, y + 5, z + 5, SamsMod.samstone, 1, 2);
		world.setBlock(x + 2, y + 5, z + 6, SamsMod.samstone, 1, 2);
		world.setBlock(x + 2, y + 5, z + 7, SamsMod.samstone, 1, 2);
		world.setBlock(x + 2, y + 5, z + 8, SamsMod.samstone, 1, 2);
		world.setBlock(x + 2, y + 5, z + 9, SamsMod.samstone, 1, 2);
		world.setBlock(x + 2, y + 5, z + 10, SamsMod.samstone, 1, 2);
		world.setBlock(x + 3, y + 0, z + 0, SamsMod.samstone, 1, 2);
		world.setBlock(x + 3, y + 0, z + 1, SamsMod.samstone, 1, 2);
		world.setBlock(x + 3, y + 0, z + 2, SamsMod.samstone, 1, 2);
		world.setBlock(x + 3, y + 0, z + 3, SamsMod.samstone, 1, 2);
		world.setBlock(x + 3, y + 0, z + 4, SamsMod.samstone, 1, 2);
		world.setBlock(x + 3, y + 0, z + 5, SamsMod.samstone, 1, 2);
		world.setBlock(x + 3, y + 0, z + 6, SamsMod.samstone, 1, 2);
		world.setBlock(x + 3, y + 0, z + 7, SamsMod.samstone, 1, 2);
		world.setBlock(x + 3, y + 0, z + 8, SamsMod.samstone, 1, 2);
		world.setBlock(x + 3, y + 0, z + 9, SamsMod.samstone, 1, 2);
		world.setBlock(x + 3, y + 0, z + 10, SamsMod.samstone, 1, 2);
		world.setBlock(x + 3, y + 1, z + 0, SamsMod.samstone, 1, 2);
		world.setBlock(x + 3, y + 1, z + 1, SamsMod.samstone, 1, 2);
		world.setBlock(x + 3, y + 1, z + 2, SamsMod.samstone, 1, 2);
		world.setBlock(x + 3, y + 1, z + 3, SamsMod.samstone, 1, 2);
		world.setBlock(x + 3, y + 1, z + 4, Blocks.air);
		world.setBlock(x + 3, y + 1, z + 5, Blocks.air);
		world.setBlock(x + 3, y + 1, z + 6, Blocks.air);
		world.setBlock(x + 3, y + 1, z + 7, SamsMod.samstone, 1, 2);
		world.setBlock(x + 3, y + 1, z + 8, SamsMod.samstone, 1, 2);
		world.setBlock(x + 3, y + 1, z + 9, SamsMod.samstone, 1, 2);
		world.setBlock(x + 3, y + 1, z + 10, SamsMod.samstone, 1, 2);
		world.setBlock(x + 3, y + 2, z + 0, SamsMod.samstone, 1, 2);
		world.setBlock(x + 3, y + 2, z + 1, SamsMod.samstone, 1, 2);
		world.setBlock(x + 3, y + 2, z + 2, SamsMod.samstone, 1, 2);
		world.setBlock(x + 3, y + 2, z + 3, Blocks.air);
		world.setBlock(x + 3, y + 2, z + 4, Blocks.air);
		world.setBlock(x + 3, y + 2, z + 5, Blocks.air);
		world.setBlock(x + 3, y + 2, z + 6, Blocks.air);
		world.setBlock(x + 3, y + 2, z + 7, Blocks.air);
		world.setBlock(x + 3, y + 2, z + 8, SamsMod.samstone, 1, 2);
		world.setBlock(x + 3, y + 2, z + 9, SamsMod.samstone, 1, 2);
		world.setBlock(x + 3, y + 2, z + 10, SamsMod.samstone, 1, 2);
		world.setBlock(x + 3, y + 3, z + 0, SamsMod.samstone, 1, 2);
		world.setBlock(x + 3, y + 3, z + 1, SamsMod.samstone, 1, 2);
		world.setBlock(x + 3, y + 3, z + 2, Blocks.air);
		world.setBlock(x + 3, y + 3, z + 3, Blocks.air);
		world.setBlock(x + 3, y + 3, z + 4, Blocks.air);
		world.setBlock(x + 3, y + 3, z + 5, Blocks.air);
		world.setBlock(x + 3, y + 3, z + 6, Blocks.air);
		world.setBlock(x + 3, y + 3, z + 7, Blocks.air);
		world.setBlock(x + 3, y + 3, z + 8, Blocks.air);
		world.setBlock(x + 3, y + 3, z + 9, SamsMod.samstone, 1, 2);
		world.setBlock(x + 3, y + 3, z + 10, SamsMod.samstone, 1, 2);
		world.setBlock(x + 3, y + 4, z + 0, SamsMod.samstone, 1, 2);
		world.setBlock(x + 3, y + 4, z + 1, Blocks.air);
		world.setBlock(x + 3, y + 4, z + 2, Blocks.air);
		world.setBlock(x + 3, y + 4, z + 3, Blocks.air);
		world.setBlock(x + 3, y + 4, z + 4, Blocks.air);
		world.setBlock(x + 3, y + 4, z + 5, Blocks.air);
		world.setBlock(x + 3, y + 4, z + 6, Blocks.air);
		world.setBlock(x + 3, y + 4, z + 7, Blocks.air);
		world.setBlock(x + 3, y + 4, z + 8, Blocks.air);
		world.setBlock(x + 3, y + 4, z + 9, Blocks.air);
		world.setBlock(x + 3, y + 4, z + 10, SamsMod.samstone, 1, 2);
		world.setBlock(x + 3, y + 5, z + 0, SamsMod.samstone, 1, 2);
		world.setBlock(x + 3, y + 5, z + 1, SamsMod.samstone, 1, 2);
		world.setBlock(x + 3, y + 5, z + 2, SamsMod.samstone, 1, 2);
		world.setBlock(x + 3, y + 5, z + 3, SamsMod.samstone, 1, 2);
		world.setBlock(x + 3, y + 5, z + 4, SamsMod.samstone, 1, 2);
		world.setBlock(x + 3, y + 5, z + 5, Blocks.glowstone);
		world.setBlock(x + 3, y + 5, z + 6, SamsMod.samstone, 1, 2);
		world.setBlock(x + 3, y + 5, z + 7, SamsMod.samstone, 1, 2);
		world.setBlock(x + 3, y + 5, z + 8, SamsMod.samstone, 1, 2);
		world.setBlock(x + 3, y + 5, z + 9, SamsMod.samstone, 1, 2);
		world.setBlock(x + 3, y + 5, z + 10, SamsMod.samstone, 1, 2);
		world.setBlock(x + 4, y + 0, z + 0, SamsMod.samstone, 1, 2);
		world.setBlock(x + 4, y + 0, z + 1, SamsMod.samstone, 1, 2);
		world.setBlock(x + 4, y + 0, z + 2, SamsMod.samstone, 1, 2);
		world.setBlock(x + 4, y + 0, z + 3, SamsMod.samstone, 1, 2);
		world.setBlock(x + 4, y + 0, z + 4, SamsMod.samstone, 1, 2);
		world.setBlock(x + 4, y + 0, z + 5, SamsMod.samstone, 1, 2);
		world.setBlock(x + 4, y + 0, z + 6, SamsMod.samstone, 1, 2);
		world.setBlock(x + 4, y + 0, z + 7, SamsMod.samstone, 1, 2);
		world.setBlock(x + 4, y + 0, z + 8, SamsMod.samstone, 1, 2);
		world.setBlock(x + 4, y + 0, z + 9, SamsMod.samstone, 1, 2);
		world.setBlock(x + 4, y + 0, z + 10, SamsMod.samstone, 1, 2);
		world.setBlock(x + 4, y + 1, z + 0, SamsMod.samstone, 1, 2);
		world.setBlock(x + 4, y + 1, z + 1, Blocks.air);
		world.setBlock(x + 4, y + 1, z + 2, Blocks.air);
		world.setBlock(x + 4, y + 1, z + 3, Blocks.air);
		world.setBlock(x + 4, y + 1, z + 4, Blocks.air);
		world.setBlock(x + 4, y + 1, z + 5, Blocks.air);
		world.setBlock(x + 4, y + 1, z + 6, Blocks.air);
		world.setBlock(x + 4, y + 1, z + 7, Blocks.air);
		world.setBlock(x + 4, y + 1, z + 8, Blocks.air);
		world.setBlock(x + 4, y + 1, z + 9, Blocks.air);
		world.setBlock(x + 4, y + 1, z + 10, SamsMod.samstone, 1, 2);
		world.setBlock(x + 4, y + 2, z + 0, SamsMod.samstone, 1, 2);
		world.setBlock(x + 4, y + 2, z + 1, Blocks.air);
		world.setBlock(x + 4, y + 2, z + 2, Blocks.air);
		world.setBlock(x + 4, y + 2, z + 3, Blocks.air);
		world.setBlock(x + 4, y + 2, z + 4, Blocks.air);
		world.setBlock(x + 4, y + 2, z + 5, Blocks.air);
		world.setBlock(x + 4, y + 2, z + 6, Blocks.air);
		world.setBlock(x + 4, y + 2, z + 7, Blocks.air);
		world.setBlock(x + 4, y + 2, z + 8, Blocks.air);
		world.setBlock(x + 4, y + 2, z + 9, Blocks.air);
		world.setBlock(x + 4, y + 2, z + 10, SamsMod.samstone, 1, 2);
		world.setBlock(x + 4, y + 3, z + 0, SamsMod.samstone, 1, 2);
		world.setBlock(x + 4, y + 3, z + 1, Blocks.air);
		world.setBlock(x + 4, y + 3, z + 2, Blocks.air);
		world.setBlock(x + 4, y + 3, z + 3, Blocks.air);
		world.setBlock(x + 4, y + 3, z + 4, Blocks.air);
		world.setBlock(x + 4, y + 3, z + 5, Blocks.air);
		world.setBlock(x + 4, y + 3, z + 6, Blocks.air);
		world.setBlock(x + 4, y + 3, z + 7, Blocks.air);
		world.setBlock(x + 4, y + 3, z + 8, Blocks.air);
		world.setBlock(x + 4, y + 3, z + 9, Blocks.air);
		world.setBlock(x + 4, y + 3, z + 10, SamsMod.samstone, 1, 2);
		world.setBlock(x + 4, y + 4, z + 0, SamsMod.samstone, 1, 2);
		world.setBlock(x + 4, y + 4, z + 1, Blocks.air);
		world.setBlock(x + 4, y + 4, z + 2, Blocks.air);
		world.setBlock(x + 4, y + 4, z + 3, Blocks.air);
		world.setBlock(x + 4, y + 4, z + 4, Blocks.air);
		world.setBlock(x + 4, y + 4, z + 5, Blocks.air);
		world.setBlock(x + 4, y + 4, z + 6, Blocks.air);
		world.setBlock(x + 4, y + 4, z + 7, Blocks.air);
		world.setBlock(x + 4, y + 4, z + 8, Blocks.air);
		world.setBlock(x + 4, y + 4, z + 9, Blocks.air);
		world.setBlock(x + 4, y + 4, z + 10, SamsMod.samstone, 1, 2);
		world.setBlock(x + 4, y + 5, z + 0, SamsMod.samstone, 1, 2);
		world.setBlock(x + 4, y + 5, z + 1, SamsMod.samstone, 1, 2);
		world.setBlock(x + 4, y + 5, z + 2, SamsMod.samstone, 1, 2);
		world.setBlock(x + 4, y + 5, z + 3, SamsMod.samstone, 1, 2);
		world.setBlock(x + 4, y + 5, z + 4, SamsMod.samstone, 1, 2);
		world.setBlock(x + 4, y + 5, z + 5, SamsMod.samstone, 1, 2);
		world.setBlock(x + 4, y + 5, z + 6, SamsMod.samstone, 1, 2);
		world.setBlock(x + 4, y + 5, z + 7, SamsMod.samstone, 1, 2);
		world.setBlock(x + 4, y + 5, z + 8, SamsMod.samstone, 1, 2);
		world.setBlock(x + 4, y + 5, z + 9, SamsMod.samstone, 1, 2);
		world.setBlock(x + 4, y + 5, z + 10, SamsMod.samstone, 1, 2);
		world.setBlock(x + 5, y + 0, z + 0, SamsMod.samstone, 1, 2);
		world.setBlock(x + 5, y + 0, z + 1, SamsMod.samstone, 1, 2);
		world.setBlock(x + 5, y + 0, z + 2, SamsMod.samstone, 1, 2);
		world.setBlock(x + 5, y + 0, z + 3, SamsMod.samstone, 1, 2);
		world.setBlock(x + 5, y + 0, z + 4, SamsMod.samstone, 1, 2);
		world.setBlock(x + 5, y + 0, z + 5, SamsMod.samstone, 1, 2);
		world.setBlock(x + 5, y + 0, z + 6, SamsMod.samstone, 1, 2);
		world.setBlock(x + 5, y + 0, z + 7, SamsMod.samstone, 1, 2);
		world.setBlock(x + 5, y + 0, z + 8, SamsMod.samstone, 1, 2);
		world.setBlock(x + 5, y + 0, z + 9, SamsMod.samstone, 1, 2);
		world.setBlock(x + 5, y + 0, z + 10, SamsMod.samstone, 1, 2);
		world.setBlock(x + 5, y + 1, z + 0, SamsMod.samstone, 1, 2);
		world.setBlock(x + 5, y + 1, z + 1, Blocks.air);
		world.setBlock(x + 5, y + 1, z + 2, Blocks.air);
		world.setBlock(x + 5, y + 1, z + 3, Blocks.air);
		world.setBlock(x + 5, y + 1, z + 4, Blocks.air);
		world.setBlock(x + 5, y + 1, z + 5, SamsMod.samstone, 1, 2);
		world.setBlock(x + 5, y + 1, z + 6, Blocks.air);
		world.setBlock(x + 5, y + 1, z + 7, Blocks.air);
		world.setBlock(x + 5, y + 1, z + 8, Blocks.air);
		world.setBlock(x + 5, y + 1, z + 9, Blocks.air);
		world.setBlock(x + 5, y + 1, z + 10, SamsMod.samstone, 1, 2);
		world.setBlock(x + 5, y + 2, z + 0, SamsMod.samstone, 1, 2);
		world.setBlock(x + 5, y + 2, z + 1, Blocks.air);
		world.setBlock(x + 5, y + 2, z + 2, Blocks.air);
		world.setBlock(x + 5, y + 2, z + 3, Blocks.air);
		world.setBlock(x + 5, y + 2, z + 4, Blocks.air);
		world.setBlock(x + 5, y + 2, z + 5, SamsMod.samstone, 1, 2);
		world.setBlock(x + 5, y + 2, z + 6, Blocks.air);
		world.setBlock(x + 5, y + 2, z + 7, Blocks.air);
		world.setBlock(x + 5, y + 2, z + 8, Blocks.air);
		world.setBlock(x + 5, y + 2, z + 9, Blocks.air);
		world.setBlock(x + 5, y + 2, z + 10, SamsMod.samstone, 1, 2);
		world.setBlock(x + 5, y + 3, z + 0, SamsMod.samstone, 1, 2);
		world.setBlock(x + 5, y + 3, z + 1, Blocks.air);
		world.setBlock(x + 5, y + 3, z + 2, Blocks.air);
		world.setBlock(x + 5, y + 3, z + 3, Blocks.air);
		world.setBlock(x + 5, y + 3, z + 4, Blocks.air);
		world.setBlock(x + 5, y + 3, z + 5, Blocks.air);
		world.setBlock(x + 5, y + 3, z + 6, Blocks.air);
		world.setBlock(x + 5, y + 3, z + 7, Blocks.air);
		world.setBlock(x + 5, y + 3, z + 8, Blocks.air);
		world.setBlock(x + 5, y + 3, z + 9, Blocks.air);
		world.setBlock(x + 5, y + 3, z + 10, SamsMod.samstone, 1, 2);
		world.setBlock(x + 5, y + 4, z + 0, SamsMod.samstone, 1, 2);
		world.setBlock(x + 5, y + 4, z + 1, Blocks.air);
		world.setBlock(x + 5, y + 4, z + 2, Blocks.air);
		world.setBlock(x + 5, y + 4, z + 3, Blocks.air);
		world.setBlock(x + 5, y + 4, z + 4, Blocks.air);
		world.setBlock(x + 5, y + 4, z + 5, Blocks.air);
		world.setBlock(x + 5, y + 4, z + 6, Blocks.air);
		world.setBlock(x + 5, y + 4, z + 7, Blocks.air);
		world.setBlock(x + 5, y + 4, z + 8, Blocks.air);
		world.setBlock(x + 5, y + 4, z + 9, Blocks.air);
		world.setBlock(x + 5, y + 4, z + 10, SamsMod.samstone, 1, 2);
		world.setBlock(x + 5, y + 5, z + 0, SamsMod.samstone, 1, 2);
		world.setBlock(x + 5, y + 5, z + 1, SamsMod.samstone, 1, 2);
		world.setBlock(x + 5, y + 5, z + 2, SamsMod.samstone, 1, 2);
		world.setBlock(x + 5, y + 5, z + 3, SamsMod.samstone, 1, 2);
		world.setBlock(x + 5, y + 5, z + 4, SamsMod.samstone, 1, 2);
		world.setBlock(x + 5, y + 5, z + 5, SamsMod.samstone, 1, 2);
		world.setBlock(x + 5, y + 5, z + 6, SamsMod.samstone, 1, 2);
		world.setBlock(x + 5, y + 5, z + 7, SamsMod.samstone, 1, 2);
		world.setBlock(x + 5, y + 5, z + 8, SamsMod.samstone, 1, 2);
		world.setBlock(x + 5, y + 5, z + 9, SamsMod.samstone, 1, 2);
		world.setBlock(x + 5, y + 5, z + 10, SamsMod.samstone, 1, 2);
		world.setBlock(x + 6, y + 0, z + 0, SamsMod.samstone, 1, 2);
		world.setBlock(x + 6, y + 0, z + 1, SamsMod.samstone, 1, 2);
		world.setBlock(x + 6, y + 0, z + 2, SamsMod.samstone, 1, 2);
		world.setBlock(x + 6, y + 0, z + 3, SamsMod.samstone, 1, 2);
		world.setBlock(x + 6, y + 0, z + 4, SamsMod.samstone, 1, 2);
		world.setBlock(x + 6, y + 0, z + 5, SamsMod.samstone, 1, 2);
		world.setBlock(x + 6, y + 0, z + 6, SamsMod.samstone, 1, 2);
		world.setBlock(x + 6, y + 0, z + 7, SamsMod.samstone, 1, 2);
		world.setBlock(x + 6, y + 0, z + 8, SamsMod.samstone, 1, 2);
		world.setBlock(x + 6, y + 0, z + 9, SamsMod.samstone, 1, 2);
		world.setBlock(x + 6, y + 0, z + 10, SamsMod.samstone, 1, 2);
		world.setBlock(x + 6, y + 1, z + 0, SamsMod.samstone, 1, 2);
		world.setBlock(x + 6, y + 1, z + 1, SamsMod.samstone, 1, 2);
		world.setBlock(x + 6, y + 1, z + 2, SamsMod.samstone, 1, 2);
		world.setBlock(x + 6, y + 1, z + 3, SamsMod.samstone, 1, 2);
		world.setBlock(x + 6, y + 1, z + 4, SamsMod.samstone, 1, 2);
		world.setBlock(x + 6, y + 1, z + 5, SamsMod.samstone, 1, 2);
		world.setBlock(x + 6, y + 1, z + 6, SamsMod.samstone, 1, 2);
		world.setBlock(x + 6, y + 1, z + 7, SamsMod.samstone, 1, 2);
		world.setBlock(x + 6, y + 1, z + 8, SamsMod.samstone, 1, 2);
		world.setBlock(x + 6, y + 1, z + 9, SamsMod.samstone, 1, 2);
		world.setBlock(x + 6, y + 1, z + 10, SamsMod.samstone, 1, 2);
		world.setBlock(x + 6, y + 2, z + 0, SamsMod.samstone, 1, 2);
		world.setBlock(x + 6, y + 2, z + 1, SamsMod.samstone, 1, 2);
		world.setBlock(x + 6, y + 2, z + 2, SamsMod.samstone, 1, 2);
		world.setBlock(x + 6, y + 2, z + 3, SamsMod.samstone, 1, 2);
		world.setBlock(x + 6, y + 2, z + 4, SamsMod.samstone, 1, 2);
		world.setBlock(x + 6, y + 2, z + 5, SamsMod.samstone, 1, 2);
		world.setBlock(x + 6, y + 2, z + 6, SamsMod.samstone, 1, 2);
		world.setBlock(x + 6, y + 2, z + 7, SamsMod.samstone, 1, 2);
		world.setBlock(x + 6, y + 2, z + 8, SamsMod.samstone, 1, 2);
		world.setBlock(x + 6, y + 2, z + 9, SamsMod.samstone, 1, 2);
		world.setBlock(x + 6, y + 2, z + 10, SamsMod.samstone, 1, 2);
		world.setBlock(x + 6, y + 3, z + 0, SamsMod.samstone, 1, 2);
		world.setBlock(x + 6, y + 3, z + 1, SamsMod.samstone, 1, 2);
		world.setBlock(x + 6, y + 3, z + 2, SamsMod.samstone, 1, 2);
		world.setBlock(x + 6, y + 3, z + 3, SamsMod.samstone, 1, 2);
		world.setBlock(x + 6, y + 3, z + 4, SamsMod.samstone, 1, 2);
		world.setBlock(x + 6, y + 3, z + 5, SamsMod.samstone, 1, 2);
		world.setBlock(x + 6, y + 3, z + 6, SamsMod.samstone, 1, 2);
		world.setBlock(x + 6, y + 3, z + 7, SamsMod.samstone, 1, 2);
		world.setBlock(x + 6, y + 3, z + 8, SamsMod.samstone, 1, 2);
		world.setBlock(x + 6, y + 3, z + 9, SamsMod.samstone, 1, 2);
		world.setBlock(x + 6, y + 3, z + 10, SamsMod.samstone, 1, 2);
		world.setBlock(x + 6, y + 4, z + 0, SamsMod.samstone, 1, 2);
		world.setBlock(x + 6, y + 4, z + 1, SamsMod.samstone, 1, 2);
		world.setBlock(x + 6, y + 4, z + 2, SamsMod.samstone, 1, 2);
		world.setBlock(x + 6, y + 4, z + 3, SamsMod.samstone, 1, 2);
		world.setBlock(x + 6, y + 4, z + 4, SamsMod.samstone, 1, 2);
		world.setBlock(x + 6, y + 4, z + 5, SamsMod.samstone, 1, 2);
		world.setBlock(x + 6, y + 4, z + 6, SamsMod.samstone, 1, 2);
		world.setBlock(x + 6, y + 4, z + 7, SamsMod.samstone, 1, 2);
		world.setBlock(x + 6, y + 4, z + 8, SamsMod.samstone, 1, 2);
		world.setBlock(x + 6, y + 4, z + 9, SamsMod.samstone, 1, 2);
		world.setBlock(x + 6, y + 4, z + 10, SamsMod.samstone, 1, 2);
		world.setBlock(x + 6, y + 5, z + 0, SamsMod.samstone, 1, 2);
		world.setBlock(x + 6, y + 5, z + 1, SamsMod.samstone, 1, 2);
		world.setBlock(x + 6, y + 5, z + 2, SamsMod.samstone, 1, 2);
		world.setBlock(x + 6, y + 5, z + 3, SamsMod.samstone, 1, 2);
		world.setBlock(x + 6, y + 5, z + 4, SamsMod.samstone, 1, 2);
		world.setBlock(x + 6, y + 5, z + 5, SamsMod.samstone, 1, 2);
		world.setBlock(x + 6, y + 5, z + 6, SamsMod.samstone, 1, 2);
		world.setBlock(x + 6, y + 5, z + 7, SamsMod.samstone, 1, 2);
		world.setBlock(x + 6, y + 5, z + 8, SamsMod.samstone, 1, 2);
		world.setBlock(x + 6, y + 5, z + 9, SamsMod.samstone, 1, 2);
		world.setBlock(x + 6, y + 5, z + 10, SamsMod.samstone, 1, 2);
		
		EntityZombie entity = new EntityZombie(world);
		entity.setPosition(x + 1, y + 2, z + 1);
		world.spawnEntityInWorld(entity);

		world.setBlock(x + 5, y + 1, z + 1, Blocks.mob_spawner);
		TileEntityMobSpawner spawner = (TileEntityMobSpawner)world.getTileEntity(x + 5, y + 1, z + 1);
				
		if (spawner != null)
		{
		    spawner.func_145881_a().setEntityName("Skeleton");
		}
		else
		{
		    System.err.println("Failed to fetch mob spawner entity at (" + x + ", " + y + ", " + z + ")");
		}

		return true;
	}
}