
package com.wuppy.samsmod;

import java.util.Random;
import net.minecraft.entity.monster.EntityZombie;
import net.minecraft.init.Blocks;
import net.minecraft.tileentity.TileEntityMobSpawner;
import net.minecraft.world.World;
import net.minecraft.world.gen.feature.WorldGenerator;


public class WorldGenSamObsidianDungeon extends WorldGenerator 
{

	public boolean generate(World world , Random rand, int x, int y, int z) {
	{	

		world.setBlock(x + 0, y + 0, z + 0, Blocks.obsidian);
		world.setBlock(x + 0, y + 0, z + 1, Blocks.obsidian);
		world.setBlock(x + 0, y + 0, z + 2, Blocks.obsidian);
		world.setBlock(x + 0, y + 0, z + 3, Blocks.obsidian);
		world.setBlock( x + 0, y + 0, z + 4, Blocks.obsidian);
		world.setBlock( x + 0, y + 0, z + 5, Blocks.obsidian);
		world.setBlock(x + 0, y + 0, z + 6, Blocks.obsidian);
		world.setBlock(x + 0, y + 0, z + 7, Blocks.obsidian);
		world.setBlock(x + 0, y + 0, z + 8, Blocks.obsidian);
		world.setBlock(x + 0, y + 0, z + 9, Blocks.obsidian);
		world.setBlock(x + 0, y + 0, z + 10, Blocks.obsidian);
		world.setBlock(x + 0, y + 0, z + 11, Blocks.obsidian);
		world.setBlock(x + 0, y + 0, z + 12, Blocks.obsidian);
		world.setBlock(x + 0, y + 0, z + 13, Blocks.obsidian);
		world.setBlock(x + 0, y + 0, z + 14, Blocks.obsidian);
		world.setBlock(x + 0, y + 1, z + 0, Blocks.obsidian);
		world.setBlock(x + 0, y + 1, z + 1, Blocks.obsidian);
		world.setBlock(x + 0, y + 1, z + 2, Blocks.obsidian);
		world.setBlock(x + 0, y + 1, z + 3, Blocks.obsidian);
		world.setBlock(x + 0, y + 1, z + 4, Blocks.obsidian);
		world.setBlock(x + 0, y + 1, z + 5, Blocks.obsidian);
		world.setBlock(x + 0, y + 1, z + 6, Blocks.obsidian);
		world.setBlock(x + 0, y + 1, z + 7, Blocks.obsidian);
		world.setBlock(x + 0, y + 1, z + 8, Blocks.obsidian);
		world.setBlock(x + 0, y + 1, z + 9, Blocks.obsidian);
		world.setBlock(x + 0, y + 1, z + 10, Blocks.obsidian);
		world.setBlock(x + 0, y + 1, z + 11, Blocks.obsidian);
		world.setBlock(x + 0, y + 1, z + 12, Blocks.obsidian);
		world.setBlock(x + 0, y + 1, z + 13, Blocks.obsidian);
		world.setBlock(x + 0, y + 1, z + 14, Blocks.obsidian);
		world.setBlock(x + 0, y + 2, z + 0, Blocks.obsidian);
		world.setBlock(x + 0, y + 2, z + 1, Blocks.obsidian);
		world.setBlock(x + 0, y + 2, z + 2, Blocks.obsidian);
		world.setBlock(x + 0, y + 2, z + 3, Blocks.obsidian);
		world.setBlock(x + 0, y + 2, z + 4, Blocks.obsidian);
		world.setBlock(x + 0, y + 2, z + 5, Blocks.obsidian);
		world.setBlock(x + 0, y + 2, z + 6, Blocks.obsidian);
		world.setBlock(x + 0, y + 2, z + 7, Blocks.obsidian);
		world.setBlock(x + 0, y + 2, z + 8, Blocks.obsidian);
		world.setBlock(x + 0, y + 2, z + 9, Blocks.obsidian);
		world.setBlock(x + 0, y + 2, z + 10, Blocks.obsidian);
		world.setBlock(x + 0, y + 2, z + 11, Blocks.obsidian);
		world.setBlock(x + 0, y + 2, z + 12, Blocks.obsidian);
		world.setBlock(x + 0, y + 2, z + 13, Blocks.obsidian);
		world.setBlock(x + 0, y + 2, z + 14, Blocks.obsidian);
		world.setBlock(x + 0, y + 3, z + 0, Blocks.obsidian);
		world.setBlock(x + 0, y + 3, z + 1, Blocks.obsidian);
		world.setBlock(x + 0, y + 3, z + 2, Blocks.obsidian);
		world.setBlock(x + 0, y + 3, z + 3, Blocks.obsidian);
		world.setBlock(x + 0, y + 3, z + 4, Blocks.obsidian);
		world.setBlock(x + 0, y + 3, z + 5, Blocks.glowstone);
		world.setBlock(x + 0, y + 3, z + 6, Blocks.obsidian);
		world.setBlock(x + 0, y + 3, z + 7, Blocks.obsidian);
		world.setBlock(x + 0, y + 3, z + 8, Blocks.obsidian);
		world.setBlock(x + 0, y + 3, z + 9, Blocks.obsidian);
		world.setBlock(x + 0, y + 3, z + 10, Blocks.obsidian);
		world.setBlock(x + 0, y + 3, z + 11, Blocks.obsidian);
		world.setBlock(x + 0, y + 3, z + 12, Blocks.obsidian);
		world.setBlock(x + 0, y + 3, z + 13, Blocks.obsidian);
		world.setBlock(x + 0, y + 3, z + 14, Blocks.obsidian);
		world.setBlock(x + 0, y + 4, z + 0, Blocks.obsidian);
		world.setBlock(x + 0, y + 4, z + 1, Blocks.obsidian);
		world.setBlock(x + 0, y + 4, z + 2, Blocks.obsidian);
		world.setBlock(x + 0, y + 4, z + 3, Blocks.obsidian);
		world.setBlock(x + 0, y + 4, z + 4, Blocks.obsidian);
		world.setBlock(x + 0, y + 4, z + 5, Blocks.obsidian);
		world.setBlock(x + 0, y + 4, z + 6, Blocks.obsidian);
		world.setBlock(x + 0, y + 4, z + 7, Blocks.obsidian);
		world.setBlock(x + 0, y + 4, z + 8, Blocks.obsidian);
		world.setBlock(x + 0, y + 4, z + 9, Blocks.obsidian);
		world.setBlock(x + 0, y + 4, z + 10, Blocks.obsidian);
		world.setBlock(x + 0, y + 4, z + 11, Blocks.obsidian);
		world.setBlock(x + 0, y + 4, z + 12, Blocks.obsidian);
		world.setBlock(x + 0, y + 4, z + 13, Blocks.obsidian);
		world.setBlock(x + 0, y + 4, z + 14, Blocks.obsidian);
		world.setBlock(x + 0, y + 5, z + 0, Blocks.obsidian);
		world.setBlock(x + 0, y + 5, z + 1, Blocks.obsidian);
		world.setBlock(x + 0, y + 5, z + 2, Blocks.obsidian);
		world.setBlock(x + 0, y + 5, z + 3, Blocks.obsidian);
		world.setBlock(x + 0, y + 5, z + 4, Blocks.obsidian);
		world.setBlock(x + 0, y + 5, z + 5, Blocks.obsidian);
		world.setBlock(x + 0, y + 5, z + 6, Blocks.obsidian);
		world.setBlock(x + 0, y + 5, z + 7, Blocks.obsidian);
		world.setBlock(x + 0, y + 5, z + 8, Blocks.obsidian);
		world.setBlock(x + 0, y + 5, z + 9, Blocks.obsidian);
		world.setBlock(x + 0, y + 5, z + 10, Blocks.obsidian);
		world.setBlock(x + 0, y + 5, z + 11, Blocks.obsidian);
		world.setBlock(x + 0, y + 5, z + 12, Blocks.obsidian);
		world.setBlock(x + 0, y + 5, z + 13, Blocks.obsidian);
		world.setBlock(x + 0, y + 5, z + 14, Blocks.obsidian);
		world.setBlock(x + 0, y + 6, z + 0, Blocks.obsidian);
		world.setBlock(x + 0, y + 6, z + 1, Blocks.obsidian);
		world.setBlock(x + 0, y + 6, z + 2, Blocks.obsidian);
		world.setBlock(x + 0, y + 6, z + 3, Blocks.obsidian);
		world.setBlock(x + 0, y + 6, z + 4, Blocks.obsidian);
		world.setBlock(x + 0, y + 6, z + 5, Blocks.obsidian);
		world.setBlock(x + 0, y + 6, z + 6, Blocks.obsidian);
		world.setBlock(x + 0, y + 6, z + 7, Blocks.obsidian);
		world.setBlock(x + 0, y + 6, z + 8, Blocks.obsidian);
		world.setBlock(x + 0, y + 6, z + 9, Blocks.obsidian);
		world.setBlock(x + 0, y + 6, z + 10, Blocks.obsidian);
		world.setBlock(x + 0, y + 6, z + 11, Blocks.obsidian);
		world.setBlock(x + 0, y + 6, z + 12, Blocks.obsidian);
		world.setBlock(x + 0, y + 6, z + 13, Blocks.obsidian);
		world.setBlock(x + 0, y + 6, z + 14, Blocks.obsidian);
		world.setBlock(x + 0, y + 7, z + 0, Blocks.obsidian);
		world.setBlock(x + 0, y + 7, z + 1, Blocks.obsidian);
		world.setBlock(x + 0, y + 7, z + 2, Blocks.obsidian);
		world.setBlock(x + 0, y + 7, z + 3, Blocks.obsidian);
		world.setBlock(x + 0, y + 7, z + 4, Blocks.obsidian);
		world.setBlock(x + 0, y + 7, z + 5, Blocks.obsidian);
		world.setBlock(x + 0, y + 7, z + 6, Blocks.obsidian);
		world.setBlock(x + 0, y + 7, z + 7, Blocks.obsidian);
		world.setBlock(x + 0, y + 7, z + 8, Blocks.obsidian);
		world.setBlock(x + 0, y + 7, z + 9, Blocks.obsidian);
		world.setBlock(x + 0, y + 7, z + 10, Blocks.obsidian);
		world.setBlock(x + 0, y + 7, z + 11, Blocks.obsidian);
		world.setBlock(x + 0, y + 7, z + 12, Blocks.obsidian);
		world.setBlock(x + 0, y + 7, z + 13, Blocks.obsidian);
		world.setBlock(x + 0, y + 7, z + 14, Blocks.obsidian);
		world.setBlock(x + 0, y + 8, z + 0, Blocks.obsidian);
		world.setBlock(x + 0, y + 8, z + 1, Blocks.obsidian);
		world.setBlock(x + 0, y + 8, z + 2, Blocks.obsidian);
		world.setBlock(x + 0, y + 8, z + 3, Blocks.obsidian);
		world.setBlock(x + 0, y + 8, z + 4, Blocks.obsidian);
		world.setBlock(x + 0, y + 8, z + 5, Blocks.obsidian);
		world.setBlock(x + 0, y + 8, z + 6, Blocks.obsidian);
		world.setBlock(x + 0, y + 8, z + 7, Blocks.obsidian);
		world.setBlock(x + 0, y + 8, z + 8, Blocks.obsidian);
		world.setBlock(x + 0, y + 8, z + 9, Blocks.obsidian);
		world.setBlock(x + 0, y + 8, z + 10, Blocks.obsidian);
		world.setBlock(x + 0, y + 8, z + 11, Blocks.obsidian);
		world.setBlock(x + 0, y + 8, z + 12, Blocks.obsidian);
		world.setBlock(x + 0, y + 8, z + 13, Blocks.obsidian);
		world.setBlock(x + 0, y + 8, z + 14, Blocks.obsidian);
		world.setBlock(x + 1, y + 0, z + 0, Blocks.obsidian);
		world.setBlock(x + 1, y + 0, z + 1, Blocks.obsidian);
		world.setBlock(x + 1, y + 0, z + 2, Blocks.obsidian);
		world.setBlock(x + 1, y + 0, z + 3, Blocks.obsidian);
		world.setBlock(x + 1, y + 0, z + 4, Blocks.obsidian);
		world.setBlock(x + 1, y + 0, z + 5, Blocks.obsidian);
		world.setBlock(x + 1, y + 0, z + 6, Blocks.obsidian);
		world.setBlock(x + 1, y + 0, z + 7, Blocks.obsidian);
		world.setBlock(x + 1, y + 0, z + 8, Blocks.obsidian);
		world.setBlock(x + 1, y + 0, z + 9, Blocks.obsidian);
		world.setBlock(x + 1, y + 0, z + 10, Blocks.obsidian);
		world.setBlock(x + 1, y + 0, z + 11, Blocks.obsidian);
		world.setBlock(x + 1, y + 0, z + 12, Blocks.obsidian);
		world.setBlock(x + 1, y + 0, z + 13, Blocks.obsidian);
		world.setBlock(x + 1, y + 0, z + 14, Blocks.obsidian);
		world.setBlock(x + 1, y + 1, z + 0, Blocks.obsidian);
		world.setBlock(x + 1, y + 1, z + 14, Blocks.obsidian);
		world.setBlock(x + 1, y + 2, z + 0, Blocks.obsidian);
		world.setBlock(x + 1, y + 2, z + 14, Blocks.obsidian);
		world.setBlock(x + 1, y + 3, z + 0, Blocks.obsidian);
		world.setBlock(x + 1, y + 3, z + 14, Blocks.obsidian);
		world.setBlock(x + 1, y + 4, z + 0, Blocks.obsidian);
		world.setBlock(x + 1, y + 4, z + 14, Blocks.obsidian);
		world.setBlock(x + 1, y + 5, z + 0, Blocks.obsidian);
		world.setBlock(x + 1, y + 5, z + 14, Blocks.obsidian);
		world.setBlock(x + 1, y + 6, z + 0, Blocks.obsidian);
		world.setBlock(x + 1, y + 6, z + 14, Blocks.obsidian);
		world.setBlock(x + 1, y + 7, z + 0, Blocks.obsidian);
		world.setBlock(x + 1, y + 7, z + 14, Blocks.obsidian);
		world.setBlock(x + 1, y + 8, z + 0, Blocks.obsidian);
		world.setBlock(x + 1, y + 8, z + 1, Blocks.obsidian);
		world.setBlock(x + 1, y + 8, z + 2, Blocks.obsidian);
		world.setBlock(x + 1, y + 8, z + 3, Blocks.obsidian);
		world.setBlock(x + 1, y + 8, z + 4, Blocks.obsidian);
		world.setBlock(x + 1, y + 8, z + 5, Blocks.obsidian);
		world.setBlock(x + 1, y + 8, z + 6, Blocks.obsidian);
		world.setBlock(x + 1, y + 8, z + 7, Blocks.obsidian);
		world.setBlock(x + 1, y + 8, z + 8, Blocks.obsidian);
		world.setBlock(x + 1, y + 8, z + 9, Blocks.obsidian);
		world.setBlock(x + 1, y + 8, z + 10, Blocks.obsidian);
		world.setBlock(x + 1, y + 8, z + 11, Blocks.obsidian);
		world.setBlock(x + 1, y + 8, z + 12, Blocks.obsidian);
		world.setBlock(x + 1, y + 8, z + 13, Blocks.obsidian);
		world.setBlock(x + 1, y + 8, z + 14, Blocks.obsidian);
		world.setBlock(x + 2, y + 0, z + 0, Blocks.obsidian);
		world.setBlock(x + 2, y + 0, z + 1, Blocks.obsidian);
		world.setBlock(x + 2, y + 0, z + 2, Blocks.obsidian);
		world.setBlock(x + 2, y + 0, z + 3, Blocks.obsidian);
		world.setBlock(x + 2, y + 0, z + 4, Blocks.obsidian);
		world.setBlock(x + 2, y + 0, z + 5, Blocks.obsidian);
		world.setBlock(x + 2, y + 0, z + 6, Blocks.obsidian);
		world.setBlock(x + 2, y + 0, z + 7, Blocks.obsidian);
		world.setBlock(x + 2, y + 0, z + 8, Blocks.obsidian);
		world.setBlock(x + 2, y + 0, z + 9, Blocks.obsidian);
		world.setBlock(x + 2, y + 0, z + 10, Blocks.obsidian);
		world.setBlock(x + 2, y + 0, z + 11, Blocks.obsidian);
		world.setBlock(x + 2, y + 0, z + 12, Blocks.obsidian);
		world.setBlock(x + 2, y + 0, z + 13, Blocks.obsidian);
		world.setBlock(x + 2, y + 0, z + 14, Blocks.obsidian);
		world.setBlock(x + 2, y + 1, z + 0, Blocks.obsidian);
		world.setBlock(x + 2, y + 1, z + 14, Blocks.obsidian);
		world.setBlock(x + 2, y + 2, z + 0, Blocks.obsidian);
		world.setBlock(x + 2, y + 2, z + 14, Blocks.obsidian);
		world.setBlock(x + 2, y + 3, z + 0, Blocks.obsidian);
		world.setBlock(x + 2, y + 3, z + 14, Blocks.obsidian);
		world.setBlock(x + 2, y + 4, z + 0, Blocks.obsidian);
		world.setBlock(x + 2, y + 4, z + 14, Blocks.obsidian);
		world.setBlock(x + 2, y + 5, z + 0, Blocks.obsidian);
		world.setBlock(x + 2, y + 5, z + 14, Blocks.obsidian);
		world.setBlock(x + 2, y + 6, z + 0, Blocks.obsidian);
		world.setBlock(x + 2, y + 6, z + 14, Blocks.obsidian);
		world.setBlock(x + 2, y + 7, z + 0, Blocks.obsidian);
		world.setBlock(x + 2, y + 7, z + 14, Blocks.obsidian);
		world.setBlock(x + 2, y + 8, z + 0, Blocks.obsidian);
		world.setBlock(x + 2, y + 8, z + 1, Blocks.obsidian);
		world.setBlock(x + 2, y + 8, z + 2, Blocks.obsidian);
		world.setBlock(x + 2, y + 8, z + 3, Blocks.obsidian);
		world.setBlock(x + 2, y + 8, z + 4, Blocks.obsidian);
		world.setBlock(x + 2, y + 8, z + 5, Blocks.obsidian);
		world.setBlock(x + 2, y + 8, z + 6, Blocks.obsidian);
		world.setBlock(x + 2, y + 8, z + 7, Blocks.obsidian);
		world.setBlock(x + 2, y + 8, z + 8, Blocks.obsidian);
		world.setBlock(x + 2, y + 8, z + 9, Blocks.obsidian);
		world.setBlock(x + 2, y + 8, z + 10, Blocks.obsidian);
		world.setBlock(x + 2, y + 8, z + 11, Blocks.glowstone);
		world.setBlock(x + 2, y + 8, z + 12, Blocks.obsidian);
		world.setBlock(x + 2, y + 8, z + 13, Blocks.obsidian);
		world.setBlock(x + 2, y + 8, z + 14, Blocks.obsidian);
		world.setBlock(x + 3, y + 0, z + 0, Blocks.obsidian);
		world.setBlock(x + 3, y + 0, z + 1, Blocks.obsidian);
		world.setBlock(x + 3, y + 0, z + 2, Blocks.obsidian);
		world.setBlock(x + 3, y + 0, z + 3, Blocks.obsidian);
		world.setBlock(x + 3, y + 0, z + 4, Blocks.obsidian);
		world.setBlock(x + 3, y + 0, z + 5, Blocks.obsidian);
		world.setBlock(x + 3, y + 0, z + 6, Blocks.obsidian);
		world.setBlock(x + 3, y + 0, z + 7, Blocks.glowstone);
		world.setBlock(x + 3, y + 0, z + 8, Blocks.obsidian);
		world.setBlock(x + 3, y + 0, z + 9, Blocks.obsidian);
		world.setBlock(x + 3, y + 0, z + 10, Blocks.glowstone);
		world.setBlock(x + 3, y + 0, z + 11, Blocks.obsidian);
		world.setBlock(x + 3, y + 0, z + 12, Blocks.obsidian);
		world.setBlock(x + 3, y + 0, z + 13, Blocks.obsidian);
		world.setBlock(x + 3, y + 0, z + 14, Blocks.obsidian);
		world.setBlock(x + 3, y + 1, z + 0, Blocks.obsidian);
		world.setBlock(x + 3, y + 1, z + 14, Blocks.obsidian);
		world.setBlock(x + 3, y + 2, z + 0, Blocks.obsidian);
		world.setBlock(x + 3, y + 2, z + 14, Blocks.obsidian);
		world.setBlock(x + 3, y + 3, z + 0, Blocks.obsidian);
		world.setBlock(x + 3, y + 3, z + 14, Blocks.obsidian);
		world.setBlock(x + 3, y + 4, z + 0, Blocks.obsidian);
		world.setBlock(x + 3, y + 4, z + 14, Blocks.obsidian);
		world.setBlock(x + 3, y + 5, z + 0, Blocks.obsidian);
		world.setBlock(x + 3, y + 5, z + 14, Blocks.obsidian);
		world.setBlock(x + 3, y + 6, z + 0, Blocks.obsidian);
		world.setBlock(x + 3, y + 6, z + 14, Blocks.obsidian);
		world.setBlock(x + 3, y + 7, z + 0, Blocks.obsidian);
		world.setBlock(x + 3, y + 7, z + 14, Blocks.obsidian);
		world.setBlock(x + 3, y + 8, z + 0, Blocks.obsidian);
		world.setBlock(x + 3, y + 8, z + 1, Blocks.obsidian);
		world.setBlock(x + 3, y + 8, z + 2, Blocks.obsidian);
		world.setBlock(x + 3, y + 8, z + 3, Blocks.glowstone);
		world.setBlock(x + 3, y + 8, z + 4, Blocks.obsidian);
		world.setBlock(x + 3, y + 8, z + 5, Blocks.obsidian);
		world.setBlock(x + 3, y + 8, z + 6, Blocks.obsidian);
		world.setBlock(x + 3, y + 8, z + 7, Blocks.obsidian);
		world.setBlock(x + 3, y + 8, z + 8, Blocks.obsidian);
		world.setBlock(x + 3, y + 8, z + 9, Blocks.obsidian);
		world.setBlock(x + 3, y + 8, z + 10, Blocks.obsidian);
		world.setBlock(x + 3, y + 8, z + 11, Blocks.obsidian);
		world.setBlock(x + 3, y + 8, z + 12, Blocks.obsidian);
		world.setBlock(x + 3, y + 8, z + 13, Blocks.obsidian);
		world.setBlock(x + 3, y + 8, z + 14, Blocks.obsidian);
		world.setBlock(x + 4, y + 0, z + 0, Blocks.obsidian);
		world.setBlock(x + 4, y + 0, z + 1, Blocks.obsidian);
		world.setBlock(x + 4, y + 0, z + 2, Blocks.obsidian);
		world.setBlock(x + 4, y + 0, z + 3, Blocks.obsidian);
		world.setBlock(x + 4, y + 0, z + 4, Blocks.obsidian);
		world.setBlock(x + 4, y + 0, z + 5, Blocks.obsidian);
		world.setBlock(x + 4, y + 0, z + 6, Blocks.obsidian);
		world.setBlock(x + 4, y + 0, z + 7, Blocks.obsidian);
		world.setBlock(x + 4, y + 0, z + 8, Blocks.obsidian);
		world.setBlock(x + 4, y + 0, z + 9, Blocks.obsidian);
		world.setBlock(x + 4, y + 0, z + 10, Blocks.obsidian);
		world.setBlock(x + 4, y + 0, z + 11, Blocks.obsidian);
		world.setBlock(x + 4, y + 0, z + 12, Blocks.obsidian);
		world.setBlock(x + 4, y + 0, z + 13, Blocks.obsidian);
		world.setBlock(x + 4, y + 0, z + 14, Blocks.obsidian);
		world.setBlock(x + 4, y + 1, z + 0, Blocks.obsidian);
		world.setBlock(x + 4, y + 1, z + 14, Blocks.obsidian);
		world.setBlock(x + 4, y + 2, z + 0, Blocks.obsidian);
		world.setBlock(x + 4, y + 2, z + 14, Blocks.obsidian);
		world.setBlock(x + 4, y + 3, z + 0, Blocks.glowstone);
		world.setBlock(x + 4, y + 3, z + 14, Blocks.obsidian);
		world.setBlock(x + 4, y + 4, z + 0, Blocks.obsidian);
		world.setBlock(x + 4, y + 4, z + 14, Blocks.obsidian);
		world.setBlock(x + 4, y + 5, z + 0, Blocks.obsidian);
		world.setBlock(x + 4, y + 5, z + 14, Blocks.obsidian);
		world.setBlock(x + 4, y + 6, z + 0, Blocks.obsidian);
		world.setBlock(x + 4, y + 6, z + 14, Blocks.obsidian);
		world.setBlock(x + 4, y + 7, z + 0, Blocks.obsidian);
		world.setBlock(x + 4, y + 7, z + 14, Blocks.obsidian);
		world.setBlock(x + 4, y + 8, z + 0, Blocks.obsidian);
		world.setBlock(x + 4, y + 8, z + 1, Blocks.obsidian);
		world.setBlock(x + 4, y + 8, z + 2, Blocks.obsidian);
		world.setBlock(x + 4, y + 8, z + 3, Blocks.obsidian);
		world.setBlock(x + 4, y + 8, z + 4, Blocks.obsidian);
		world.setBlock(x + 4, y + 8, z + 5, Blocks.obsidian);
		world.setBlock(x + 4, y + 8, z + 6, Blocks.obsidian);
		world.setBlock(x + 4, y + 8, z + 7, Blocks.obsidian);
		world.setBlock(x + 4, y + 8, z + 8, Blocks.glowstone);
		world.setBlock(x + 4, y + 8, z + 9, Blocks.obsidian);
		world.setBlock(x + 4, y + 8, z + 10, Blocks.obsidian);
		world.setBlock(x + 4, y + 8, z + 11, Blocks.obsidian);
		world.setBlock(x + 4, y + 8, z + 12, Blocks.obsidian);
		world.setBlock(x + 4, y + 8, z + 13, Blocks.obsidian);
		world.setBlock(x + 4, y + 8, z + 14, Blocks.obsidian);
		world.setBlock(x + 5, y + 0, z + 0, Blocks.obsidian);
		world.setBlock(x + 5, y + 0, z + 1, Blocks.obsidian);
		world.setBlock(x + 5, y + 0, z + 2, Blocks.obsidian);
		world.setBlock(x + 5, y + 0, z + 3, Blocks.glowstone);
		world.setBlock(x + 5, y + 0, z + 4, Blocks.obsidian);
		world.setBlock(x + 5, y + 0, z + 5, Blocks.obsidian);
		world.setBlock(x + 5, y + 0, z + 6, Blocks.obsidian);
		world.setBlock(x + 5, y + 0, z + 7, Blocks.obsidian);
		world.setBlock(x + 5, y + 0, z + 8, Blocks.obsidian);
		world.setBlock(x + 5, y + 0, z + 9, Blocks.obsidian);
		world.setBlock(x + 5, y + 0, z + 10, Blocks.obsidian);
		world.setBlock(x + 5, y + 0, z + 11, Blocks.obsidian);
		world.setBlock(x + 5, y + 0, z + 12, Blocks.obsidian);
		world.setBlock(x + 5, y + 0, z + 13, Blocks.obsidian);
		world.setBlock(x + 5, y + 0, z + 14, Blocks.obsidian);
		world.setBlock(x + 5, y + 1, z + 0, Blocks.obsidian);
		world.setBlock(x + 5, y + 1, z + 7, Blocks.dispenser, 5, z);
		world.setBlock(x + 5, y + 1, z + 14, Blocks.obsidian);
		world.setBlock(x + 5, y + 2, z + 0, Blocks.obsidian);
		world.setBlock(x + 5, y + 2, z + 14, Blocks.obsidian);
		world.setBlock(x + 5, y + 3, z + 0, Blocks.obsidian);
		world.setBlock(x + 5, y + 3, z + 14, Blocks.obsidian);
		world.setBlock(x + 5, y + 4, z + 0, Blocks.obsidian);
		world.setBlock(x + 5, y + 4, z + 14, Blocks.obsidian);
		world.setBlock(x + 5, y + 5, z + 0, Blocks.obsidian);
		world.setBlock(x + 5, y + 5, z + 14, Blocks.obsidian);
		world.setBlock(x + 5, y + 6, z + 0, Blocks.obsidian);
		world.setBlock(x + 5, y + 6, z + 14, Blocks.obsidian);
		world.setBlock(x + 5, y + 7, z + 0, Blocks.obsidian);
		world.setBlock(x + 5, y + 7, z + 14, Blocks.obsidian);
		world.setBlock(x + 5, y + 8, z + 0, Blocks.obsidian);
		world.setBlock(x + 5, y + 8, z + 1, Blocks.obsidian);
		world.setBlock(x + 5, y + 8, z + 2, Blocks.obsidian);
		world.setBlock(x + 5, y + 8, z + 3, Blocks.obsidian);
		world.setBlock(x + 5, y + 8, z + 4, Blocks.obsidian);
		world.setBlock(x + 5, y + 8, z + 5, Blocks.glowstone);
		world.setBlock(x + 5, y + 8, z + 6, Blocks.obsidian);
		world.setBlock(x + 5, y + 8, z + 7, Blocks.obsidian);
		world.setBlock(x + 5, y + 8, z + 8, Blocks.obsidian);
		world.setBlock(x + 5, y + 8, z + 9, Blocks.obsidian);
		world.setBlock(x + 5, y + 8, z + 10, Blocks.obsidian);
		world.setBlock(x + 5, y + 8, z + 11, Blocks.obsidian);
		world.setBlock(x + 5, y + 8, z + 12, Blocks.obsidian);
		world.setBlock(x + 5, y + 8, z + 13, Blocks.obsidian);
		world.setBlock(x + 5, y + 8, z + 14, Blocks.obsidian);
		world.setBlock(x + 6, y + 0, z + 0, Blocks.obsidian);
		world.setBlock(x + 6, y + 0, z + 1, Blocks.obsidian);
		world.setBlock(x + 6, y + 0, z + 2, Blocks.obsidian);
		world.setBlock(x + 6, y + 0, z + 3, Blocks.obsidian);
		world.setBlock(x + 6, y + 0, z + 4, Blocks.obsidian);
		world.setBlock(x + 6, y + 0, z + 5, Blocks.glowstone);
		world.setBlock(x + 6, y + 0, z + 6, Blocks.obsidian);
		world.setBlock(x + 6, y + 0, z + 7, Blocks.obsidian);
		world.setBlock(x + 6, y + 0, z + 8, Blocks.obsidian);
		world.setBlock(x + 6, y + 0, z + 9, Blocks.obsidian);
		world.setBlock(x + 6, y + 0, z + 10, Blocks.obsidian);
		world.setBlock(x + 6, y + 0, z + 11, Blocks.obsidian);
		world.setBlock(x + 6, y + 0, z + 12, Blocks.obsidian);
		world.setBlock(x + 6, y + 0, z + 13, Blocks.obsidian);
		world.setBlock(x + 6, y + 0, z + 14, Blocks.obsidian);
		world.setBlock(x + 6, y + 1, z + 0, Blocks.obsidian);
		world.setBlock(x + 6, y + 1, z + 14, Blocks.obsidian);
		world.setBlock(x + 6, y + 2, z + 0, Blocks.obsidian);
		world.setBlock(x + 6, y + 2, z + 14, Blocks.obsidian);
		world.setBlock(x + 6, y + 3, z + 0, Blocks.obsidian);
		world.setBlock(x + 6, y + 3, z + 14, Blocks.glowstone);
		world.setBlock(x + 6, y + 4, z + 0, Blocks.obsidian);
		world.setBlock(x + 6, y + 4, z + 14, Blocks.obsidian);
		world.setBlock(x + 6, y + 5, z + 0, Blocks.obsidian);
		world.setBlock(x + 6, y + 5, z + 14, Blocks.obsidian);
		world.setBlock(x + 6, y + 6, z + 0, Blocks.obsidian);
		world.setBlock(x + 6, y + 6, z + 14, Blocks.obsidian);
		world.setBlock(x + 6, y + 7, z + 0, Blocks.obsidian);
		world.setBlock(x + 6, y + 7, z + 14, Blocks.obsidian);
		world.setBlock(x + 6, y + 8, z + 0, Blocks.obsidian);
		world.setBlock(x + 6, y + 8, z + 1, Blocks.obsidian);
		world.setBlock(x + 6, y + 8, z + 2, Blocks.obsidian);
		world.setBlock(x + 6, y + 8, z + 3, Blocks.obsidian);
		world.setBlock(x + 6, y + 8, z + 4, Blocks.obsidian);
		world.setBlock(x + 6, y + 8, z + 5, Blocks.obsidian);
		world.setBlock(x + 6, y + 8, z + 6, Blocks.obsidian);
		world.setBlock(x + 6, y + 8, z + 7, Blocks.obsidian);
		world.setBlock(x + 6, y + 8, z + 8, Blocks.obsidian);
		world.setBlock(x + 6, y + 8, z + 9, Blocks.obsidian);
		world.setBlock(x + 6, y + 8, z + 10, Blocks.obsidian);
		world.setBlock(x + 6, y + 8, z + 11, Blocks.obsidian);
		world.setBlock(x + 6, y + 8, z + 12, Blocks.obsidian);
		world.setBlock(x + 6, y + 8, z + 13, Blocks.obsidian);
		world.setBlock(x + 6, y + 8, z + 14, Blocks.obsidian);
		world.setBlock(x + 7, y + 0, z + 0, Blocks.obsidian);
		world.setBlock(x + 7, y + 0, z + 1, Blocks.obsidian);
		world.setBlock(x + 7, y + 0, z + 2, Blocks.obsidian);
		world.setBlock(x + 7, y + 0, z + 3, Blocks.obsidian);
		world.setBlock(x + 7, y + 0, z + 4, Blocks.obsidian);
		world.setBlock(x + 7, y + 0, z + 5, Blocks.obsidian);
		world.setBlock(x + 7, y + 0, z + 6, Blocks.obsidian);
		world.setBlock(x + 7, y + 0, z + 7, Blocks.obsidian);
		world.setBlock(x + 7, y + 0, z + 8, Blocks.obsidian);
		world.setBlock(x + 7, y + 0, z + 9, Blocks.obsidian);
		world.setBlock(x + 7, y + 0, z + 10, Blocks.obsidian);
		world.setBlock(x + 7, y + 0, z + 11, Blocks.obsidian);
		world.setBlock(x + 7, y + 0, z + 12, Blocks.obsidian);
		world.setBlock(x + 7, y + 0, z + 13, Blocks.obsidian);
		world.setBlock(x + 7, y + 0, z + 14, Blocks.obsidian);
		world.setBlock(x + 7, y + 1, z + 0, Blocks.obsidian);
		world.setBlock(x + 7, y + 1, z + 7, Blocks.dispenser);
		world.setBlock(x + 7, y + 1, z + 14, Blocks.obsidian);
		world.setBlock(x + 7, y + 2, z + 0, Blocks.obsidian);
		world.setBlock(x + 7, y + 2, z + 14, Blocks.obsidian);
		world.setBlock(x + 7, y + 3, z + 0, Blocks.obsidian);
		world.setBlock(x + 7, y + 3, z + 14, Blocks.obsidian);
		world.setBlock(x + 7, y + 4, z + 0, Blocks.obsidian);
		world.setBlock(x + 7, y + 4, z + 14, Blocks.obsidian);
		world.setBlock(x + 7, y + 5, z + 0, Blocks.obsidian);
		world.setBlock(x + 7, y + 5, z + 14, Blocks.obsidian);
		world.setBlock(x + 7, y + 6, z + 0, Blocks.obsidian);
		world.setBlock(x + 7, y + 6, z + 14, Blocks.obsidian);
		world.setBlock(x + 7, y + 7, z + 0, Blocks.obsidian);
		world.setBlock(x + 7, y + 7, z + 14, Blocks.obsidian);
		world.setBlock(x + 7, y + 8, z + 0, Blocks.obsidian);
		world.setBlock(x + 7, y + 8, z + 1, Blocks.obsidian);
		world.setBlock(x + 7, y + 8, z + 2, Blocks.glowstone);
		world.setBlock(x + 7, y + 8, z + 3, Blocks.obsidian);
		world.setBlock(x + 7, y + 8, z + 4, Blocks.obsidian);
		world.setBlock(x + 7, y + 8, z + 5, Blocks.obsidian);
		world.setBlock(x + 7, y + 8, z + 6, Blocks.obsidian);
		world.setBlock(x + 7, y + 8, z + 7, Blocks.obsidian);
		world.setBlock(x + 7, y + 8, z + 8, Blocks.obsidian);
		world.setBlock(x + 7, y + 8, z + 9, Blocks.obsidian);
		world.setBlock(x + 7, y + 8, z + 10, Blocks.obsidian);
		world.setBlock(x + 7, y + 8, z + 11, Blocks.obsidian);
		world.setBlock(x + 7, y + 8, z + 12, Blocks.obsidian);
		world.setBlock(x + 7, y + 8, z + 13, Blocks.obsidian);
		world.setBlock(x + 7, y + 8, z + 14, Blocks.obsidian);
		world.setBlock(x + 8, y + 0, z + 0, Blocks.obsidian);
		world.setBlock(x + 8, y + 0, z + 1, Blocks.obsidian);
		world.setBlock(x + 8, y + 0, z + 2, Blocks.obsidian);
		world.setBlock(x + 8, y + 0, z + 3, Blocks.obsidian);
		world.setBlock(x + 8, y + 0, z + 4, Blocks.obsidian);
		world.setBlock(x + 8, y + 0, z + 5, Blocks.obsidian);
		world.setBlock(x + 8, y + 0, z + 6, Blocks.obsidian);
		world.setBlock(x + 8, y + 0, z + 7, Blocks.obsidian);
		world.setBlock(x + 8, y + 0, z + 8, Blocks.glowstone);
		world.setBlock(x + 8, y + 0, z + 9, Blocks.obsidian);
		world.setBlock(x + 8, y + 0, z + 10, Blocks.obsidian);
		world.setBlock(x + 8, y + 0, z + 11, Blocks.obsidian);
		world.setBlock(x + 8, y + 0, z + 12, Blocks.obsidian);
		world.setBlock(x + 8, y + 0, z + 13, Blocks.obsidian);
		world.setBlock(x + 8, y + 0, z + 14, Blocks.obsidian);
		world.setBlock(x + 8, y + 1, z + 0, Blocks.obsidian);
		world.setBlock(x + 8, y + 1, z + 14, Blocks.obsidian);
		world.setBlock(x + 8, y + 2, z + 0, Blocks.obsidian);
		world.setBlock(x + 8, y + 2, z + 14, Blocks.obsidian);
		world.setBlock(x + 8, y + 3, z + 0, Blocks.obsidian);
		world.setBlock(x + 8, y + 3, z + 14, Blocks.obsidian);
		world.setBlock(x + 8, y + 4, z + 0, Blocks.obsidian);
		world.setBlock(x + 8, y + 4, z + 14, Blocks.obsidian);
		world.setBlock(x + 8, y + 5, z + 0, Blocks.obsidian);
		world.setBlock(x + 8, y + 5, z + 14, Blocks.obsidian);
		world.setBlock(x + 8, y + 6, z + 0, Blocks.obsidian);
		world.setBlock(x + 8, y + 6, z + 14, Blocks.obsidian);
		world.setBlock(x + 8, y + 7, z + 0, Blocks.obsidian);
		world.setBlock(x + 8, y + 7, z + 14, Blocks.obsidian);
		world.setBlock(x + 8, y + 8, z + 0, Blocks.obsidian);
		world.setBlock(x + 8, y + 8, z + 1, Blocks.obsidian);
		world.setBlock(x + 8, y + 8, z + 2, Blocks.obsidian);
		world.setBlock(x + 8, y + 8, z + 3, Blocks.obsidian);
		world.setBlock(x + 8, y + 8, z + 4, Blocks.obsidian);
		world.setBlock(x + 8, y + 8, z + 5, Blocks.obsidian);
		world.setBlock(x + 8, y + 8, z + 6, Blocks.obsidian);
		world.setBlock(x + 8, y + 8, z + 7, Blocks.obsidian);
		world.setBlock(x + 8, y + 8, z + 8, Blocks.obsidian);
		world.setBlock(x + 8, y + 8, z + 9, Blocks.obsidian);
		world.setBlock(x + 8, y + 8, z + 10, Blocks.obsidian);
		world.setBlock(x + 8, y + 8, z + 11, Blocks.glowstone);
		world.setBlock(x + 8, y + 8, z + 12, Blocks.obsidian);
		world.setBlock(x + 8, y + 8, z + 13, Blocks.obsidian);
		world.setBlock(x + 8, y + 8, z + 14, Blocks.obsidian);
		world.setBlock(x + 9, y + 0, z + 0, Blocks.obsidian);
		world.setBlock(x + 9, y + 0, z + 1, Blocks.obsidian);
		world.setBlock(x + 9, y + 0, z + 2, Blocks.obsidian);
		world.setBlock(x + 9, y + 0, z + 3, Blocks.obsidian);
		world.setBlock(x + 9, y + 0, z + 4, Blocks.obsidian);
		world.setBlock(x + 9, y + 0, z + 5, Blocks.obsidian);
		world.setBlock(x + 9, y + 0, z + 6, Blocks.obsidian);
		world.setBlock(x + 9, y + 0, z + 7, Blocks.obsidian);
		world.setBlock(x + 9, y + 0, z + 8, Blocks.obsidian);
		world.setBlock(x + 9, y + 0, z + 9, Blocks.obsidian);
		world.setBlock(x + 9, y + 0, z + 10, Blocks.obsidian);
		world.setBlock(x + 9, y + 0, z + 11, Blocks.glowstone);
		world.setBlock(x + 9, y + 0, z + 12, Blocks.obsidian);
		world.setBlock(x + 9, y + 0, z + 13, Blocks.obsidian);
		world.setBlock(x + 9, y + 0, z + 14, Blocks.obsidian);
		world.setBlock(x + 9, y + 1, z + 0, Blocks.obsidian);
		//world.setBlock(x + 9, y + 1, z + 1, Blocks.PistonStickyBase, 3);
		world.setBlock(x + 9, y + 1, z + 14, Blocks.obsidian);
		world.setBlock(x + 9, y + 2, z + 0, Blocks.obsidian);
		world.setBlock(x + 9, y + 2, z + 14, Blocks.obsidian);
		world.setBlock(x + 9, y + 3, z + 0, Blocks.glowstone);
		world.setBlock(x + 9, y + 3, z + 14, Blocks.obsidian);
		world.setBlock(x + 9, y + 4, z + 0, Blocks.obsidian);
		world.setBlock(x + 9, y + 4, z + 14, Blocks.obsidian);
		world.setBlock(x + 9, y + 5, z + 0, Blocks.obsidian);
		world.setBlock(x + 9, y + 5, z + 14, Blocks.obsidian);
		world.setBlock(x + 9, y + 6, z + 0, Blocks.obsidian);
		world.setBlock(x + 9, y + 6, z + 14, Blocks.obsidian);
		world.setBlock(x + 9, y + 7, z + 0, Blocks.obsidian);
		world.setBlock(x + 9, y + 7, z + 14, Blocks.obsidian);
		world.setBlock(x + 9, y + 8, z + 0, Blocks.obsidian);
		world.setBlock(x + 9, y + 8, z + 1, Blocks.obsidian);
		world.setBlock(x + 9, y + 8, z + 2, Blocks.obsidian);
		world.setBlock(x + 9, y + 8, z + 3, Blocks.obsidian);
		world.setBlock(x + 9, y + 8, z + 4, Blocks.obsidian);
		world.setBlock(x + 9, y + 8, z + 5, Blocks.obsidian);
		world.setBlock(x + 9, y + 8, z + 6, Blocks.obsidian);
		world.setBlock(x + 9, y + 8, z + 7, Blocks.obsidian);
		world.setBlock(x + 9, y + 8, z + 8, Blocks.obsidian);
		world.setBlock(x + 9, y + 8, z + 9, Blocks.obsidian);
		world.setBlock(x + 9, y + 8, z + 10, Blocks.obsidian);
		world.setBlock(x + 9, y + 8, z + 11, Blocks.obsidian);
		world.setBlock(x + 9, y + 8, z + 12, Blocks.obsidian);
		world.setBlock(x + 9, y + 8, z + 13, Blocks.obsidian);
		world.setBlock(x + 9, y + 8, z + 14, Blocks.obsidian);
		world.setBlock(x + 10, y + 0, z + 0, Blocks.obsidian);
		world.setBlock(x + 10, y + 0, z + 1, Blocks.obsidian);
		world.setBlock(x + 10, y + 0, z + 2, Blocks.obsidian);
		world.setBlock(x + 10, y + 0, z + 3, Blocks.glowstone);
		world.setBlock(x + 10, y + 0, z + 4, Blocks.obsidian);
		world.setBlock(x + 10, y + 0, z + 5, Blocks.obsidian);
		world.setBlock(x + 10, y + 0, z + 6, Blocks.obsidian);
		world.setBlock(x + 10, y + 0, z + 7, Blocks.obsidian);
		world.setBlock(x + 10, y + 0, z + 8, Blocks.obsidian);
		world.setBlock(x + 10, y + 0, z + 9, Blocks.obsidian);
		world.setBlock(x + 10, y + 0, z + 10, Blocks.obsidian);
		world.setBlock(x + 10, y + 0, z + 11, Blocks.obsidian);
		world.setBlock(x + 10, y + 0, z + 12, Blocks.obsidian);
		world.setBlock(x + 10, y + 0, z + 13, Blocks.obsidian);
		world.setBlock(x + 10, y + 0, z + 14, Blocks.obsidian);
		world.setBlock(x + 10, y + 1, z + 0, Blocks.obsidian);
		//world.setBlock(x + 10, y + 1, z + 1, Blocks.PistonStickyBase);
		world.setBlock(x + 10, y + 1, z + 14, Blocks.obsidian);
		world.setBlock(x + 10, y + 2, z + 0, Blocks.obsidian);
		world.setBlock(x + 10, y + 2, z + 14, Blocks.obsidian);
		world.setBlock(x + 10, y + 3, z + 0, Blocks.obsidian);
		world.setBlock(x + 10, y + 3, z + 14, Blocks.obsidian);
		world.setBlock(x + 10, y + 4, z + 0, Blocks.obsidian);
		world.setBlock(x + 10, y + 4, z + 14, Blocks.obsidian);
		world.setBlock(x + 10, y + 5, z + 0, Blocks.obsidian);
		world.setBlock(x + 10, y + 5, z + 14, Blocks.obsidian);
		world.setBlock(x + 10, y + 6, z + 0, Blocks.obsidian);
		world.setBlock(x + 10, y + 6, z + 14, Blocks.obsidian);
		world.setBlock(x + 10, y + 7, z + 0, Blocks.obsidian);
		world.setBlock(x + 10, y + 7, z + 14, Blocks.obsidian);
		world.setBlock(x + 10, y + 8, z + 0, Blocks.obsidian);
		world.setBlock(x + 10, y + 8, z + 1, Blocks.obsidian);
		world.setBlock(x + 10, y + 8, z + 2, Blocks.obsidian);
		world.setBlock(x + 10, y + 8, z + 3, Blocks.obsidian);
		world.setBlock(x + 10, y + 8, z + 4, Blocks.obsidian);
		world.setBlock(x + 10, y + 8, z + 5, Blocks.glowstone);
		world.setBlock(x + 10, y + 8, z + 6, Blocks.obsidian);
		world.setBlock(x + 10, y + 8, z + 7, Blocks.obsidian);
		world.setBlock(x + 10, y + 8, z + 8, Blocks.obsidian);
		world.setBlock(x + 10, y + 8, z + 9, Blocks.obsidian);
		world.setBlock(x + 10, y + 8, z + 10, Blocks.glowstone);
		world.setBlock(x + 10, y + 8, z + 11, Blocks.obsidian);
		world.setBlock(x + 10, y + 8, z + 12, Blocks.obsidian);
		world.setBlock(x + 10, y + 8, z + 13, Blocks.obsidian);
		world.setBlock(x + 10, y + 8, z + 14, Blocks.obsidian);
		world.setBlock(x + 11, y + 0, z + 0, Blocks.obsidian);
		world.setBlock(x + 11, y + 0, z + 1, Blocks.obsidian);
		world.setBlock(x + 11, y + 0, z + 2, Blocks.obsidian);
		world.setBlock(x + 11, y + 0, z + 3, Blocks.obsidian);
		world.setBlock(x + 11, y + 0, z + 4, Blocks.obsidian);
		world.setBlock(x + 11, y + 0, z + 5, Blocks.obsidian);
		world.setBlock(x + 11, y + 0, z + 6, Blocks.obsidian);
		world.setBlock(x + 11, y + 0, z + 7, Blocks.obsidian);
		world.setBlock(x + 11, y + 0, z + 8, Blocks.obsidian);
		world.setBlock(x + 11, y + 0, z + 9, Blocks.obsidian);
		world.setBlock(x + 11, y + 0, z + 10, Blocks.obsidian);
		world.setBlock(x + 11, y + 0, z + 11, Blocks.obsidian);
		world.setBlock(x + 11, y + 0, z + 12, Blocks.obsidian);
		world.setBlock(x + 11, y + 0, z + 13, Blocks.obsidian);
		world.setBlock(x + 11, y + 0, z + 14, Blocks.obsidian);
		world.setBlock(x + 11, y + 1, z + 0, Blocks.obsidian);
		world.setBlock(x + 11, y + 1, z + 14, Blocks.obsidian);
		world.setBlock(x + 11, y + 2, z + 0, Blocks.obsidian);
		world.setBlock(x + 11, y + 2, z + 14, Blocks.obsidian);
		world.setBlock(x + 11, y + 3, z + 0, Blocks.obsidian);
		world.setBlock(x + 11, y + 3, z + 14, Blocks.obsidian);
		world.setBlock(x + 11, y + 4, z + 0, Blocks.obsidian);
		world.setBlock(x + 11, y + 4, z + 14, Blocks.obsidian);
		world.setBlock(x + 11, y + 5, z + 0, Blocks.obsidian);
		world.setBlock(x + 11, y + 5, z + 14, Blocks.obsidian);
		world.setBlock(x + 11, y + 6, z + 0, Blocks.obsidian);
		world.setBlock(x + 11, y + 6, z + 14, Blocks.obsidian);
		world.setBlock(x + 11, y + 7, z + 0, Blocks.obsidian);
		world.setBlock(x + 11, y + 7, z + 14, Blocks.obsidian);
		world.setBlock(x + 11, y + 8, z + 0, Blocks.obsidian);
		world.setBlock(x + 11, y + 8, z + 1, Blocks.obsidian);
		world.setBlock(x + 11, y + 8, z + 2, Blocks.obsidian);
		world.setBlock(x + 11, y + 8, z + 3, Blocks.obsidian);
		world.setBlock(x + 11, y + 8, z + 4, Blocks.obsidian);
		world.setBlock(x + 11, y + 8, z + 5, Blocks.obsidian);
		world.setBlock(x + 11, y + 8, z + 6, Blocks.obsidian);
		world.setBlock(x + 11, y + 8, z + 7, Blocks.obsidian);
		world.setBlock(x + 11, y + 8, z + 8, Blocks.obsidian);
		world.setBlock(x + 11, y + 8, z + 9, Blocks.obsidian);
		world.setBlock(x + 11, y + 8, z + 10, Blocks.obsidian);
		world.setBlock(x + 11, y + 8, z + 11, Blocks.obsidian);
		world.setBlock(x + 11, y + 8, z + 12, Blocks.obsidian);
		world.setBlock(x + 11, y + 8, z + 13, Blocks.obsidian);
		world.setBlock(x + 11, y + 8, z + 14, Blocks.obsidian);
		world.setBlock(x + 12, y + 0, z + 0, Blocks.obsidian);
		world.setBlock(x + 12, y + 0, z + 1, Blocks.obsidian);
		world.setBlock(x + 12, y + 0, z + 2, Blocks.obsidian);
		world.setBlock(x + 12, y + 0, z + 3, Blocks.obsidian);
		world.setBlock(x + 12, y + 0, z + 4, Blocks.obsidian);
		world.setBlock(x + 12, y + 0, z + 5, Blocks.obsidian);
		world.setBlock(x + 12, y + 0, z + 6, Blocks.obsidian);
		world.setBlock(x + 12, y + 0, z + 7, Blocks.obsidian);
		world.setBlock(x + 12, y + 0, z + 8, Blocks.obsidian);
		world.setBlock(x + 12, y + 0, z + 9, Blocks.obsidian);
		world.setBlock(x + 12, y + 0, z + 10, Blocks.obsidian);
		world.setBlock(x + 12, y + 0, z + 11, Blocks.obsidian);
		world.setBlock(x + 12, y + 0, z + 12, Blocks.obsidian);
		world.setBlock(x + 12, y + 0, z + 13, Blocks.obsidian);
		world.setBlock(x + 12, y + 0, z + 14, Blocks.obsidian);
		world.setBlock(x + 12, y + 1, z + 0, Blocks.obsidian);
		world.setBlock(x + 12, y + 1, z + 14, Blocks.obsidian);
		world.setBlock(x + 12, y + 2, z + 0, Blocks.obsidian);
		world.setBlock(x + 12, y + 2, z + 14, Blocks.obsidian);
		world.setBlock(x + 12, y + 3, z + 0, Blocks.obsidian);
		world.setBlock(x + 12, y + 3, z + 14, Blocks.obsidian);
		world.setBlock(x + 12, y + 4, z + 0, Blocks.obsidian);
		world.setBlock(x + 12, y + 4, z + 14, Blocks.obsidian);
		world.setBlock(x + 12, y + 5, z + 0, Blocks.obsidian);
		world.setBlock(x + 12, y + 5, z + 14, Blocks.obsidian);
		world.setBlock(x + 12, y + 6, z + 0, Blocks.obsidian);
		world.setBlock(x + 12, y + 6, z + 14, Blocks.obsidian);
		world.setBlock(x + 12, y + 7, z + 0, Blocks.obsidian);
		world.setBlock(x + 12, y + 7, z + 14, Blocks.obsidian);
		world.setBlock(x + 12, y + 8, z + 0, Blocks.obsidian);
		world.setBlock(x + 12, y + 8, z + 1, Blocks.obsidian);
		world.setBlock(x + 12, y + 8, z + 2, Blocks.glowstone);
		world.setBlock(x + 12, y + 8, z + 3, Blocks.obsidian);
		world.setBlock(x + 12, y + 8, z + 4, Blocks.obsidian);
		world.setBlock(x + 12, y + 8, z + 5, Blocks.obsidian);
		world.setBlock(x + 12, y + 8, z + 6, Blocks.obsidian);
		world.setBlock(x + 12, y + 8, z + 7, Blocks.obsidian);
		world.setBlock(x + 12, y + 8, z + 8, Blocks.obsidian);
		world.setBlock(x + 12, y + 8, z + 9, Blocks.obsidian);
		world.setBlock(x + 12, y + 8, z + 10, Blocks.obsidian);
		world.setBlock(x + 12, y + 8, z + 11, Blocks.obsidian);
		world.setBlock(x + 12, y + 8, z + 12, Blocks.obsidian);
		world.setBlock(x + 12, y + 8, z + 13, Blocks.obsidian);
		world.setBlock(x + 12, y + 8, z + 14, Blocks.obsidian);
		world.setBlock(x + 13, y + 0, z + 0, Blocks.obsidian);
		world.setBlock(x + 13, y + 0, z + 1, Blocks.obsidian);
		world.setBlock(x + 13, y + 0, z + 2, Blocks.obsidian);
		world.setBlock(x + 13, y + 0, z + 3, Blocks.obsidian);
		world.setBlock(x + 13, y + 0, z + 4, Blocks.obsidian);
		world.setBlock(x + 13, y + 0, z + 5, Blocks.obsidian);
		world.setBlock(x + 13, y + 0, z + 6, Blocks.obsidian);
		world.setBlock(x + 13, y + 0, z + 7, Blocks.obsidian);
		world.setBlock(x + 13, y + 0, z + 8, Blocks.obsidian);
		world.setBlock(x + 13, y + 0, z + 9, Blocks.obsidian);
		world.setBlock(x + 13, y + 0, z + 10, Blocks.obsidian);
		world.setBlock(x + 13, y + 0, z + 11, Blocks.obsidian);
		world.setBlock(x + 13, y + 0, z + 12, Blocks.obsidian);
		world.setBlock(x + 13, y + 0, z + 13, Blocks.obsidian);
		world.setBlock(x + 13, y + 0, z + 14, Blocks.obsidian);
		world.setBlock(x + 13, y + 1, z + 0, Blocks.obsidian);
		world.setBlock(x + 13, y + 1, z + 1, Blocks.obsidian);
		world.setBlock(x + 13, y + 1, z + 2, Blocks.obsidian);
		world.setBlock(x + 13, y + 1, z + 3, Blocks.obsidian);
		world.setBlock(x + 13, y + 1, z + 4, Blocks.obsidian);
		world.setBlock(x + 13, y + 1, z + 5, Blocks.obsidian);
		world.setBlock(x + 13, y + 1, z + 6, Blocks.obsidian);
		world.setBlock(x + 13, y + 1, z + 7, Blocks.obsidian);
		world.setBlock(x + 13, y + 1, z + 8, Blocks.obsidian);
		world.setBlock(x + 13, y + 1, z + 9, Blocks.obsidian);
		world.setBlock(x + 13, y + 1, z + 10, Blocks.obsidian);
		world.setBlock(x + 13, y + 1, z + 11, Blocks.obsidian);
		world.setBlock(x + 13, y + 1, z + 12, Blocks.obsidian);
		world.setBlock(x + 13, y + 1, z + 13, Blocks.obsidian);
		world.setBlock(x + 13, y + 1, z + 14, Blocks.obsidian);
		world.setBlock(x + 13, y + 2, z + 0, Blocks.obsidian);
		world.setBlock(x + 13, y + 2, z + 1, Blocks.obsidian);
		world.setBlock(x + 13, y + 2, z + 2, Blocks.obsidian);
		world.setBlock(x + 13, y + 2, z + 3, Blocks.obsidian);
		world.setBlock(x + 13, y + 2, z + 4, Blocks.obsidian);
		world.setBlock(x + 13, y + 2, z + 5, Blocks.obsidian);
		world.setBlock(x + 13, y + 2, z + 6, Blocks.obsidian);
		world.setBlock(x + 13, y + 2, z + 7, Blocks.glowstone);
		world.setBlock(x + 13, y + 2, z + 8, Blocks.obsidian);
		world.setBlock(x + 13, y + 2, z + 9, Blocks.obsidian);
		world.setBlock(x + 13, y + 2, z + 10, Blocks.obsidian);
		world.setBlock(x + 13, y + 2, z + 11, Blocks.obsidian);
		world.setBlock(x + 13, y + 2, z + 12, Blocks.obsidian);
		world.setBlock(x + 13, y + 2, z + 13, Blocks.obsidian);
		world.setBlock(x + 13, y + 2, z + 14, Blocks.obsidian);
		world.setBlock(x + 13, y + 3, z + 0, Blocks.obsidian);
		world.setBlock(x + 13, y + 3, z + 1, Blocks.obsidian);
		world.setBlock(x + 13, y + 3, z + 2, Blocks.obsidian);
		world.setBlock(x + 13, y + 3, z + 3, Blocks.obsidian);
		world.setBlock(x + 13, y + 3, z + 4, Blocks.obsidian);
		world.setBlock(x + 13, y + 3, z + 5, Blocks.obsidian);
		world.setBlock(x + 13, y + 3, z + 6, Blocks.obsidian);
		world.setBlock(x + 13, y + 3, z + 7, Blocks.obsidian);
		world.setBlock(x + 13, y + 3, z + 8, Blocks.obsidian);
		world.setBlock(x + 13, y + 3, z + 9, Blocks.obsidian);
		world.setBlock(x + 13, y + 3, z + 10, Blocks.obsidian);
		world.setBlock(x + 13, y + 3, z + 11, Blocks.obsidian);
		world.setBlock(x + 13, y + 3, z + 12, Blocks.obsidian);
		world.setBlock(x + 13, y + 3, z + 13, Blocks.obsidian);
		world.setBlock(x + 13, y + 3, z + 14, Blocks.obsidian);
		world.setBlock(x + 13, y + 4, z + 0, Blocks.obsidian);
		world.setBlock(x + 13, y + 4, z + 1, Blocks.obsidian);
		world.setBlock(x + 13, y + 4, z + 2, Blocks.obsidian);
		world.setBlock(x + 13, y + 4, z + 3, Blocks.obsidian);
		world.setBlock(x + 13, y + 4, z + 4, Blocks.glowstone);
		world.setBlock(x + 13, y + 4, z + 5, Blocks.obsidian);
		world.setBlock(x + 13, y + 4, z + 6, Blocks.obsidian);
		world.setBlock(x + 13, y + 4, z + 7, Blocks.obsidian);
		world.setBlock(x + 13, y + 4, z + 8, Blocks.obsidian);
		world.setBlock(x + 13, y + 4, z + 9, Blocks.obsidian);
		world.setBlock(x + 13, y + 4, z + 10, Blocks.obsidian);
		world.setBlock(x + 13, y + 4, z + 11, Blocks.obsidian);
		world.setBlock(x + 13, y + 4, z + 12, Blocks.obsidian);
		world.setBlock(x + 13, y + 4, z + 13, Blocks.obsidian);
		world.setBlock(x + 13, y + 4, z + 14, Blocks.obsidian);
		world.setBlock(x + 13, y + 5, z + 0, Blocks.obsidian);
		world.setBlock(x + 13, y + 5, z + 1, Blocks.obsidian);
		world.setBlock(x + 13, y + 5, z + 2, Blocks.obsidian);
		world.setBlock(x + 13, y + 5, z + 3, Blocks.obsidian);
		world.setBlock(x + 13, y + 5, z + 4, Blocks.obsidian);
		world.setBlock(x + 13, y + 5, z + 5, Blocks.obsidian);
		world.setBlock(x + 13, y + 5, z + 6, Blocks.obsidian);
		world.setBlock(x + 13, y + 5, z + 7, Blocks.obsidian);
		world.setBlock(x + 13, y + 5, z + 8, Blocks.obsidian);
		world.setBlock(x + 13, y + 5, z + 9, Blocks.obsidian);
		world.setBlock(x + 13, y + 5, z + 10, Blocks.obsidian);
		world.setBlock(x + 13, y + 5, z + 11, Blocks.obsidian);
		world.setBlock(x + 13, y + 5, z + 12, Blocks.obsidian);
		world.setBlock(x + 13, y + 5, z + 13, Blocks.obsidian);
		world.setBlock(x + 13, y + 5, z + 14, Blocks.obsidian);
		world.setBlock(x + 13, y + 6, z + 0, Blocks.obsidian);
		world.setBlock(x + 13, y + 6, z + 1, Blocks.obsidian);
		world.setBlock(x + 13, y + 6, z + 2, Blocks.obsidian);
		world.setBlock(x + 13, y + 6, z + 3, Blocks.obsidian);
		world.setBlock(x + 13, y + 6, z + 4, Blocks.obsidian);
		world.setBlock(x + 13, y + 6, z + 5, Blocks.obsidian);
		world.setBlock(x + 13, y + 6, z + 6, Blocks.obsidian);
		world.setBlock(x + 13, y + 6, z + 7, Blocks.obsidian);
		world.setBlock(x + 13, y + 6, z + 8, Blocks.obsidian);
		world.setBlock(x + 13, y + 6, z + 9, Blocks.obsidian);
		world.setBlock(x + 13, y + 6, z + 10, Blocks.obsidian);
		world.setBlock(x + 13, y + 6, z + 11, Blocks.obsidian);
		world.setBlock(x + 13, y + 6, z + 12, Blocks.obsidian);
		world.setBlock(x + 13, y + 6, z + 13, Blocks.obsidian);
		world.setBlock(x + 13, y + 6, z + 14, Blocks.obsidian);
		world.setBlock(x + 13, y + 7, z + 0, Blocks.obsidian);
		world.setBlock(x + 13, y + 7, z + 1, Blocks.obsidian);
		world.setBlock(x + 13, y + 7, z + 2, Blocks.obsidian);
		world.setBlock(x + 13, y + 7, z + 3, Blocks.obsidian);
		world.setBlock(x + 13, y + 7, z + 4, Blocks.obsidian);
		world.setBlock(x + 13, y + 7, z + 5, Blocks.obsidian);
		world.setBlock(x + 13, y + 7, z + 6, Blocks.obsidian);
		world.setBlock(x + 13, y + 7, z + 7, Blocks.obsidian);
		world.setBlock(x + 13, y + 7, z + 8, Blocks.obsidian);
		world.setBlock(x + 13, y + 7, z + 9, Blocks.obsidian);
		world.setBlock(x + 13, y + 7, z + 10, Blocks.obsidian);
		world.setBlock(x + 13, y + 7, z + 11, Blocks.obsidian);
		world.setBlock(x + 13, y + 7, z + 12, Blocks.obsidian);
		world.setBlock(x + 13, y + 7, z + 13, Blocks.obsidian);
		world.setBlock(x + 13, y + 7, z + 14, Blocks.obsidian);
		world.setBlock(x + 13, y + 8, z + 0, Blocks.obsidian);
		world.setBlock(x + 13, y + 8, z + 1, Blocks.obsidian);
		world.setBlock(x + 13, y + 8, z + 2, Blocks.obsidian);
		world.setBlock(x + 13, y + 8, z + 3, Blocks.obsidian);
		world.setBlock(x + 13, y + 8, z + 4, Blocks.obsidian);
		world.setBlock(x + 13, y + 8, z + 5, Blocks.obsidian);
		world.setBlock(x + 13, y + 8, z + 6, Blocks.obsidian);
		world.setBlock(x + 13, y + 8, z + 7, Blocks.obsidian);
		world.setBlock(x + 13, y + 8, z + 8, Blocks.obsidian);
		world.setBlock(x + 13, y + 8, z + 9, Blocks.obsidian);
		world.setBlock(x + 13, y + 8, z + 10, Blocks.obsidian);
		world.setBlock(x + 13, y + 8, z + 11, Blocks.obsidian);
		world.setBlock(x + 13, y + 8, z + 12, Blocks.obsidian);
		world.setBlock(x + 13, y + 8, z + 13, Blocks.obsidian);
		world.setBlock(x + 13, y + 8, z + 14, Blocks.obsidian);

		return true;
	}
}
}
	//@Override
	//public void generate(Random random, int chunkX, int chunkZ,  ,
		//	IChunkProvider chunkGenerator, IChunkProvider chunkProvider) {
		// TODO Auto-generated method stub
		
	//}